Workbook

Sheet STS.INVOICE
A1: PROFORMA INVOICE FOR SHINTS
A3: No | B3: HS_No | C3: Matl Name | D3: Unit Price | E3: Q'ty | F3: Unit | G3: Amount | H3: Country | I3: Weight | K3: Width | L3: Composition
A4: 1 | B4: 5903.20-0000 | C4: (11150-AOP) REC SM5242I-DC POLYESTER VERSION OF SM5242 - AOP | D4: 5.85 | E4: 777 | F4: YD | G4: 4545.45 | H4: Korea | I4: 4.94 | J4: kg | L4: POLYESTER 100%
A5: 2 | B5: 6005.37-0000 | C5: MESH (open) | D5: 2.8 | E5: 100 | F5: YD | G5: 280 | H5: Korea | I5: 0.64 | J5: kg | K5: 44/46", | L5: POLYESTER 100%
A6: 3 | B6: 5903.20-0000 | C6: SU107W 2L | D6: 2.4491 | E6: 200 | F6: YD | G6: 489.82 | H6: Korea | I6: 1.27 | J6: kg | L6: POLYESTER 100%
A7: 4 | B7: 5903.20-0000 | C7: SU10W 2L | D7: 2.4524 | E7: 330 | F7: YD | G7: 809.29 | H7: Korea | I7: 2.1 | J7: kg | L7: POLYESTER 100%
A8: 5 | B8: 6004.10-0000 | C8: POWER NET | D8: 2.84 | E8: 363 | F8: YD | G8: 1030.92 | H8: Korea | I8: 2.31 | J8: kg | L8: NYLON 84%/SPAN 16%
A9: 6 | B9: 6004.10-0000 | C9: LYCRA (FULL DULL SPANDEX) | D9: 4.05 | E9: 531 | F9: YD | G9: 2150.55 | H9: Korea | I9: 3.37 | J9: kg | K9: 58/60" | L9: NYLON 80%/SPAN 20%
A10: 7 | B10: 9607.19-1000 | C10: #5 PL ZIP O/E(N) ZA C6 | D10: 0.7314 | E10: 11078 | F10: PC | G10: 8102.45 | H10: Korea | I10: 70.38 | J10: kg
A11: 8 | B11: 9607.19-1000 | C11: #5 PL ZIP O/E(N) ZA H3 | D11: 0.7328 | E11: 4468 | F11: PC | G11: 3274.15 | H11: Korea | I11: 28.39 | J11: kg
A12: 9 | B12: 9606.29-9000 | C12: (BUT SN7)(BUT SN7)SNAP A-HEAD | D12: 0.02 | E12: 34958 | F12: PC | G12: 699.16 | H12: Korea | I12: 222.11 | J12: kg
A13: 10 | B13: 9606.29-9000 | C13: (BUT SN7)SNAP B-SOCKET(RING) | D13: 0.02 | E13: 34958 | F13: PC | G13: 699.16 | H13: Korea | I13: 222.11 | J13: kg
A14: 11 | B14: 9606.29-9000 | C14: (BUT SN7)SNAP C-STUD(RING) | D14: 0.01 | E14: 48660 | F14: PC | G14: 486.6 | H14: Korea | I14: 309.17 | J14: kg
A15: 12 | B15: 9606.29-9000 | C15: (BUT SN7)SNAP D-POST(RING) | D15: 0.01 | E15: 48660 | F15: PC | G15: 486.6 | H15: Korea | I15: 309.17 | J15: kg
A16: 13 | B16: 4821.10-0000 | C16: (MPHG140) Disclaimer leaflet new logo apparel | D16: 0.09 | E16: 900 | F16: PC | G16: 81 | H16: Korea | I16: 5.72 | J16: kg
A17: 14 | B17: 3926.20-0000 | C17: (MTHK005)GLOVE CLIP | D17: 0.02 | E17: 3807 | F17: PC | G17: 76.14 | H17: Korea | I17: 24.18 | J17: kg
A18: 15 | B18: 3926.20-0000 | C18: (MTHK007)PLASTIC HOOK | D18: 0.04 | E18: 12199 | F18: PC | G18: 487.96 | H18: Korea | I18: 77.5 | J18: kg
A19: 16 | B19: 8308.10-2000 | C19: (MTVV004)EYELET(N) | D19: 0.02 | E19: 54490 | F19: SET | G19: 1089.8 | H19: Korea | I19: 346.21 | J19: kg
A20: 17 | B20: 3923.50-0000 | C20: BEAD STOPPER | D20: 0.0595 | E20: 21630 | F20: PC | G20: 1286.98 | H20: Korea | I20: 137.43 | J20: kg
A21: 18 | B21: 6117.80-9000 | C21: ELASTIC BIAS TAPE(접밴드) | D21: 0.1626 | E21: 4300 | F21: YD | G21: 699.18 | H21: Korea | I21: 27.32 | J21: kg
... A52: 49 | B52: 4809.90-1000 | C52: TRANSFER PAPER FOR PROTECTION | D52: 114.88 | E52: 25 | F52: RL | G52: 2872 | H52: Korea | I52: 0.15 | J52: kg
B53: GRAND TOTAL : | E53: ==SUM(E4:E52) | G53: ==SUM(G4:G52) | I53: ==SUM(I4:I52) | J53: kg

Sheet P
A1: DETAIL PACKING LIST FOR
A3: Supplier | B3: DESCRIPTION | C3: COLOR | D3: SPEC | E3: UNIT | F3: IN-Q'TY | G3: C/T Q'ty | H3: C/T No. | I3: Remark
A4: (BR)브래니티(구,인성클로웨어) | B4: NATIONAL GEOGRAPHIC MAIN/SIZE LABEL | C4: BLACK | D4: XXXL, 115 (ML-08 for MEN TOP) | E4: PC | F4: 93 | G4: 1 | H4: box-20260311
A5: (BR)브래니티(구,인성클로웨어) | B5: NATIONAL GEOGRAPHIC MAIN/SIZE LABEL | C5: BLACK | D5: XXL, 110 (ML-08 for MEN TOP) | E5: PC | F5: 273
A6: (BR)브래니티(구,인성클로웨어) | B6: NATIONAL GEOGRAPHIC MAIN/SIZE LABEL | C6: BLACK | D6: S, 90 (ML-08 for MEN TOP) | E6: PC | F6: 389
A7: (BR)브래니티(구,인성클로웨어) | B7: NATIONAL GEOGRAPHIC MAIN/SIZE LABEL | C7: BLACK | D7: XL, 105 (ML-08 for MEN TOP) | E7: PC | F7: 709
A8: (BR)브래니티(구,인성클로웨어) | B8: NATIONAL GEOGRAPHIC MAIN/SIZE LABEL | C8: BLACK | D8: M, 95 (ML-08 for MEN TOP) | E8: PC | F8: 713
A9: (BR)브래니티(구,인성클로웨어) | B9: NATIONAL GEOGRAPHIC MAIN/SIZE LABEL | C9: BLACK | D9: L, 100 (ML-08 for MEN TOP) | E9: PC | F9: 891
A10: (HUG)지퍼백허그 | B10: THISISNEVERTHAT POLY BAG | C10: - | D10: T03 (from 24SS) | E10: PC | F10: 4220 | G10: 47 | H10: box-20260310 | I10: PO26-0181/PO26-0182/PO25-1844/PO26-0247 MIXED BOX
A11: (HUG)지퍼백허그 | B11: THISISNEVERTHAT POLY BAG | C11: - | D11: T03 (from 24SS) | E11: PC | F11: 8438
A12: (HUG)지퍼백허그 | B12: THISISNEVERTHAT POLY BAG | C12: - | D12: T02 (from 24SS) | E12: PC | F12: 424
A13: (HUG)지퍼백허그 | B13: THISISNEVERTHAT POLY BAG | C13: - | D13: T03 (from 24SS) | E13: PC | F13: 2126
A14: (HUG)지퍼백허그 | B14: THISISNEVERTHAT POLY BAG | C14: - | D14: T03 (from 24SS) | E14: PC | F14: 3186
A15: (HUG)지퍼백허그 | B15: THISISNEVERTHAT POLY BAG | C15: - | D15: T03 (from 24SS) | E15: PC | F15: 874
A16: (MARKET)한성비니루 | B16: PVC Memory form 1.8mm | C16: White | D16: 140cm | E16: M | F16: 30 | G16: 2 | H16: box-20260312
A17: (MARKET)한성비니루 | B17: PVC Memory form 3mm | C17: White | D17: 140cm | E17: M | F17: 30
A18: (MB)엠비에프지 | B18: NATIONAL GEOGRAPHIC SNAP | C18: BLACK | D18: 15MM SG-04 (A+B+C+D part+washer) | E18: SET | F18: 102 | G18: 2 | H18: box-20260310 | I18: PO25-1517/PO25-1518/PO25-1519/PO25-1516 MIXED BOX
A19: (MB)엠비에프지 | B19: NATIONAL GEOGRAPHIC SNAP | C19: BLACK | D19: 15MM SG-04 (A+B+C+D part+washer) | E19: SET | F19: 1196
A20: (MB)엠비에프지 | B20: NATIONAL GEOGRAPHIC WAPPEN | C20: B-MI/KHAKI | D20: 11CM WP-89 | E20: PC | F20: 3
A21: (MB)엠비에프지 | B21: NATIONAL GEOGRAPHIC WAPPEN | C21: B-W/SAND | D21: 11CM WP-89 | E21: PC | F21: 3
A22: (MB)엠비에프지 | B22: NATIONAL GEOGRAPHIC WAPPEN | C22: B-W/SAND | D22: 11CM WP-89 | E22: PC | F22: 206
A23: (MB)엠비에프지 | B23: NATIONAL GEOGRAPHIC WAPPEN | C23: B-MI/KHAKI | D23: 11CM WP-89 | E23: PC | F23: 308
A24: (MB)엠비에프지 | B24: EYELET(N) | C24: BLACK | D24: #2 EY-01 (A+B+1washer) | E24: SET | F24: 157
A25: (MB)엠비에프지 | B25: EYELET(N) | C25: BLACK | D25: #2 EY-01 (A+B+1washer) | E25: SET | F25: 1547
A26: (MB)엠비에프지 | B26: NATIONAL GEOGRAPHIC SNAP | C26: BLACK | D26: 15MM SG-04 (A+B+C+D part+washer) | E26: SET | F26: 843
A27: (MB)엠비에프지 | B27: EYELET(N) | C27: BLACK | D27: #2 EY-01 (A+B+1washer) | E27: SET | F27: 2106
A28: (MB)엠비에프지 | B28: NATIONAL GEOGRAPHIC SNAP | C28: BLACK | D28: 15MM SG-04 (A+B+C+D part+washer) | E28: SET | F28: 527
A29: (MB)엠비에프지 | B29: HOOK TYPE | C29: BLACK | D29: 17MM SN-19 마이깡 | E29: SET | F29: 29
A30: (MB)엠비에프지 | B30: HOOK TYPE | C30: BLACK | D30: 17MM SN-19 마이깡 | E30: SET | F30: 821
A31: (MB)엠비에프지 | B31: NATIONAL GEOGRAPHIC SNAP | C31: BLACK | D31: 15MM SG-04 (A+B+C+D part+washer) | E31: SET | F31: 842
A32: (MB)엠비에프지 | B32: EYELET(N) | C32: STORM BLUE | D32: #2 EY-01 (A+B+1washer) | E32: SET | F32: 122 | G32: 1 | H32: box-20260311
A33: (MB)엠비에프지 | B33: EYELET(N) | C33: SILVER BIRCH | D33: #2 EY-01 (A+B+1washer) | E33: SET | F33: 155
A34: (MB)엠비에프지 | B34: EYELET(N) | C34: BLACK | D34: #2 EY-01 (A+B+1washer) | E34: SET | F34: 229
A35: (MB)엠비에프지 | B35: EYELET(N) | C35: STORM BLUE | D35: #2 EY-01 (A+B+1washer) | E35: SET | F35: 5838
A36: (MB)엠비에프지 | B36: EYELET(N) | C36: SILVER BIRCH | D36: #2 EY-01 (A+B+1washer) | E36: SET | F36: 7505
A37: (MB)엠비에프지 | B37: EYELET(N) | C37: BLACK | D37: #2 EY-01 (A+B+1washer) | E37: SET | F37: 11671
A38: (MSG)엠에스지트레이딩 | B38: POWER NET | C38: BLACK | D38: 52/54" DY-098 SP16/NY84mm | E38: YD | F38: 363 | G38: 3 | H38: box-20260312
A39: (NA)나비드 | B39: BEAD STOPPER | C39: BLACK | D39: NV-ST-82 (대형비드) | E39: PC | F39: 4 | G39: 4 | H39: box-20260311
A40: (NA)나비드 | B40: BEAD STOPPER | C40: BLACK | D40: NV-ST-82 (대형비드) | E40: PC | F40: 193
A41: (NA)나비드 | B41: BEAD STOPPER | C41: BLACK | D41: NV-ST-82 (대형비드) | E41: PC | F41: 521
...

Sheet C.INV
A1: COMMERCIAL INVOICE
A2: 1) Shipper/ Exporter : | G2: 8) No & Date of Invoice
A3: Shin Textile Solutions Co., Ltd.
A4: 801,E&C Venture Dreamtower 2, 55, Digital-ro 33-gil, | G4: STB-S26-010 | K4: 46095.625
A5: Guro-gu, Seoul, Korea | G5: 9) No & Date L/C
A6: TEL :070-4659-3337 FAX :02-6330-2019
A7: 2) Consignee :
A8: SHINTS BVT CO.,LTD VAT:0800006025 | G8: 10) L/C issuing bank
A9: PHU TAO RESIDENTIAL AREA, THACH KHOI WARD,
A10: HAI PHONG CITY, VIETNAM
A11: TEL :84-320-3861-727 FAX :84-320-3861-730 | G11: 11) Remarks:
A12: XNK-Thy Ha <thyha@shintsbvt.com>
A13: 3) Notify party :
A14: THE SAME AS ABOVE
A16: 4) Port of loading: | D16: 5) Final Destination:
A18: INCHEON, KOREA | D18: HAIPHONG, VIETNAM
A19: 6) Carrier | D19: 7) Sailing on/ or About
A22: 12) Marks and Number of PKGS | D22: 13) Description of Goods | G22: 14) Quantity/Uint | I22: 15) Unit/price | J22: 16) Amount
G24: (CPT HANOI,VEITNAM)
A25: SHINTS BVT
A26: (IN DIA)
D27: MATERIALS FOR GARMENT
A28: STYLE NO.:
A29: ITEM :
A30: Q'TY :
A31: C/T NO. : | D31: TOTAL | J31: ==VLOOKUP("GRAND TOTAL :",BVT.INV!B:I,6,0)
A40: TEL NO. : 070-4006-3700~14, (DIR. 070-4006-3727)
A41: FAX NO. : (02)6330-2019 | H41: 17).Signed by :

Sheet BVT.INV
A1: PROFORMA INVOICE FOR BVT
A3: No | B3: HS_No | C3: Matl Name | D3: Unit Price | E3: Q'ty | F3: Unit | G3: Amount | H3: Country | I3: Weight | K3: HS Name | L3: Width | M3: Composition
A4: 1 | B4: 5903.20-0000 | C4: (11150-AOP) REC SM5242I-DC POLYESTER VERSION OF SM5242 - AOP | D4: 5.85 | E4: 777 | F4: YD | G4: 4545.45 | H4: Korea | I4: 4.94 | J4: kg | K4: PU COATED FABRIC | M4: POLYESTER 100%
A5: 2 | B5: 5903.20-0000 | C5: CH-31188-C0A2FLW(10K/10K) | D5: 6.29 | E5: 267 | F5: YD | G5: 1679.43 | H5: Korea | I5: 1.7 | J5: kg | K5: CH#3092-P2T | L5: 54"(Cuttable), | M5: POLYESTER 100%
A6: 3 | B6: 5903.20-0000 | C6: CH-31298-C0A2FLW(10K/10K) | D6: 5.15 | E6: 8 | F6: YD | G6: 41.2 | H6: Korea | I6: 0.05 | J6: kg | K6: PU COATED FABRIC | L6: 54"(Cuttable), | M6: POLYESTER 100%
A7: 4 | B7: 5407.69-2000 | C7: CH-32046- C0ADWRCIRE | D7: 2.55 | E7: 50 | F7: YD | G7: 127.5 | H7: Korea | I7: 0.32 | J7: kg | K7: PP TWILL PEACH | L7: 55"(Cuttable), | M7: POLYESTER 100%
A8: 5 | B8: 6005.37-0000 | C8: MESH (open) | D8: 2.8 | E8: 100 | F8: YD | G8: 280 | H8: Korea | I8: 0.64 | J8: kg | K8: MESH(HANJU) | L8: 44/46", | M8: POLYESTER 100%
A9: 6 | B9: 6005.37.0000 | C9: SANDWICH AIR MESH (CH-31963-PD) | D9: 4.15 | E9: 524 | F9: YD | G9: 2174.6 | H9: Korea | I9: 3.34 | J9: kg | K9: AIR MESH | L9: 52/54" | M9: POLYESTER 100%
A10: 7 | B10: 5903.20-0000 | C10: SU107W 2L | D10: 2.4491 | E10: 200 | F10: YD | G10: 489.82 | H10: Korea | I10: 1.27 | J10: kg | K10: PU COATED FABRIC | M10: POLYESTER 100%
A11: 8 | B11: 5903.20-0000 | C11: SU10W 2L | D11: 2.4524 | E11: 330 | F11: YD | G11: 809.29 | H11: Korea | I11: 2.1 | J11: kg | K11: PU COATED FABRIC | M11: POLYESTER 100%
A12: 9 | B12: 6004.10-0000 | C12: POWER NET | D12: 2.84 | E12: 363 | F12: YD | G12: 1030.92 | H12: Korea | I12: 2.31 | J12: kg | K12: SPAN KNIT FABRIC | M12: NYLON 84%/SPAN 16%
A13: 10 | B13: 6004.10-0000 | C13: LYCRA (FULL DULL SPANDEX) | D13: 4.05 | E13: 531 | F13: YD | G13: 2150.55 | H13: Korea | I13: 3.37 | J13: kg | K13: SPAN KNIT FABRIC | L13: 58/60" | M13: NYLON 80%/SPAN 20%
A14: 11 | B14: 5903.20-000 | C14: (MFWS005)(RIF09)BX-ESK1717-XPL | D14: 8.75 | E14: 790 | F14: YD | G14: 6912.5 | H14: Korea | I14: 5.02 | J14: kg | K14: BX-ESK1717-XPL | L14: 42" | M14: NYLON 61%/POLYESTER 31%/SPAN 8%
A15: 12 | B15: 5407.42-0000 | C15: (MFWS006)(RIF05)BX-ESK1717 | D15: 6.5 | E15: 499 | F15: YD | G15: 3243.5 | H15: Korea | I15: 3.17 | J15: kg | K15: Synthetic Woven Fabric | L15: 42", | M15: NYLON 61%/POLYESTER 31%/SPAN 8%
A16: 13 | B16: 6006.90-0000 | C16: (TSR-C7907) Rib 1X1 | D16: 0.3309 | E16: 4232 | F16: PC | G16: 1400.37 | H16: Korea | I16: 26.9 | J16: kg | K16: DRY ZONE II | M16: COTTON 82%/POLYESTER 14%/SPAN 4%
A17: 14 | B17: 9607.19-1000 | C17: #5 PL ZIP O/E(N) ZA C6 | D17: 0.7314 | E17: 11078 | F17: PC | G17: 8102.45 | H17: Korea | I17: 70.38 | J17: kg | K17: PLASTIC/NYLON ZIPPER
A18: 15 | B18: 9607.19-1000 | C18: #5 PL ZIP O/E(N) ZA H3 | D18: 0.7328 | E18: 4468 | F18: PC | G18: 3274.15 | H18: Korea | I18: 28.39 | J18: kg | K18: PLASTIC/NYLON ZIPPER
A19: 16 | B19: 9606.29-9000 | C19: (BUT SN7)(BUT SN7)SNAP A-HEAD | D19: 0.02 | E19: 34958 | F19: PC | G19: 699.16 | H19: Korea | I19: 222.11 | J19: kg | K19: SNAP BUTTON
A20: 17 | B20: 9606.29-9000 | C20: (BUT SN7)SNAP B-SOCKET(RING) | D20: 0.02 | E20: 34958 | F20: PC | G20: 699.16 | H20: Korea | I20: 222.11 | J20: kg | K20: SNAP BUTTON
A21: 18 | B21: 9606.29-9000 | C21: (BUT SN7)SNAP C-STUD(RING) | D21: 0.01 | E21: 48660 | F21: PC | G21: 486.6 | H21: Korea | I21: 309.17 | J21: kg | K21: SNAP BUTTON
A22: 19 | B22: 9606.29-9000 | C22: (BUT SN7)SNAP D-POST(RING) | D22: 0.01 | E22: 48660 | F22: PC | G22: 486.6 | H22: Korea | I22: 309.17 | J22: kg | K22: SNAP BUTTON
A23: 20 | B23: 4821.10-0000 | C23: (MPHG140) Disclaimer leaflet new logo apparel | D23: 0.09 | E23: 900 | F23: PC | G23: 81 | H23: Korea | I23: 5.72 | J23: kg | K23: HANG TAG
A24: 21 | B24: 3926.20-0000 | C24: (MTHK005)GLOVE CLIP | D24: 0.02 | E24: 3807 | F24: PC | G24: 76.14 | H24: Korea | I24: 24.18 | J24: kg | K24: PLASTIC ACCESSORY FOR GARMENTS
A25: 22 | B25: 3926.20-0000 | C25: (MTHK007)PLASTIC HOOK | D25: 0.04 | E25: 12199 | F25: PC | G25: 487.96 | H25: Korea | I25: 77.5 | J25: kg | K25: PLASTIC ACCESSORY FOR GARMENTS
A26: 23 | B26: 8308.10-2000 | C26: (MTVV004)EYELET(N) | D26: 0.02 | E26: 54490 | F26: SET | G26: 1089.8 | H26: Korea | I26: 346.21 | J26: kg | K26: METAL EYELET
A27: 24 | B27: 3923.50-0000 | C27: BEAD STOPPER | D27: 0.0595 | E27: 21630 | F27: PC | G27: 1286.98 | H27: Korea | I27: 137.43 | J27: kg | K27: PLASTIC STOPPER
A28: 25 | B28: 6117.80-9000 | C28: ELASTIC BIAS TAPE(접밴드) | D28: 0.1626 | E28: 4300 | F28: YD | G28: 699.18 | H28: Korea | I28: 27.32 | J28: kg | K28: ELASTIC BIAS TAPE
... A59: 56 | B59: 4809.90-1000 | C59: TRANSFER PAPER FOR PROTECTION | D59: 114.88 | E59: 25 | F59: RL | G59: 2872 | H59: Korea | I59: 0.15 | J59: kg | K59: TRANSFER PAPER
B60: GRAND TOTAL : | E60: ==SUM(E4:E59) | G60: ==SUM(G4:G59) | I60: ==SUM(I4:I59) | J60: kg

Sheet D.INV
A1: PROFORMA INVOICE FOR PF26S0080SB | I1: STB-S26-010
A3: No. | B3: ORDER No. | C3: STYLE | D3: QUANTITY | E3: UNIT | F3: DELIVERY
A4: 1 | B4: SB26-S0007 | C4: SAMPLE | D4: 1 | F4: 46095.625
A6: No. | B6: HS No | C6: Hs Name | D6: Unit Price | E6: Q'ty | F6: Unit | G6: Amount | H6: Country | I6: Weight
A7: 1 | B7: 5903.10-0000 | C7: PVC Memory form 1.8mm | D7: 3.83 | E7: 30 | F7: M | G7: 114.9 | H7: Korea | I7: 0.19 | J7: kg | K7: PVC
A8: 2 | B8: 5903.10-0000 | C8: PVC Memory form 3mm | D8: 5.41 | E8: 30 | F8: M | G8: 162.3 | H8: Korea | I8: 0.19 | J8: kg | K8: PVC
B9: GRAND TOTAL : | E9: ==SUM(E7:E8) | G9: ==SUM(G7:G8)
A11: PROFORMA INVOICE FOR PF26S0081SB | B11: PROFORMA INVOICE FOR PF26S0080SB | C11: PROFORMA INVOICE FOR PF26S0080SB | D11: PROFORMA INVOICE FOR PF26S0080SB | E11: PROFORMA INVOICE FOR PF26S0080SB | F11: PROFORMA INVOICE FOR PF26S0080SB | G11: PROFORMA INVOICE FOR PF26S0080SB
A13: No. | B13: ORDER No. | C13: STYLE | D13: QUANTITY | E13: UNIT | F13: DELIVERY
A14: 1 | B14: SB26-S0008 | C14: SAMPLE | D14: 1 | F14: 46095.625
A16: No. | B16: HS No | C16: Hs Name | D16: Unit Price | E16: Q'ty | F16: Unit | G16: Amount | H16: Country | I16: Weight
A17: 1 | B17: 3215.11-4000 | C17: INK FOR INK JET PLOTTER(구형기계용) | D17: 19.6 | E17: 36 | F17: PC | G17: 705.6 | H17: Korea | I17: 0.23 | J17: kg | K17: SCREEN PRINT INK
A18: 2 | B18: 3215.11-4000 | C18: ITALY INK FOR INK JET PLOTTER(신형기계용) | D18: 30.41 | E18: 24 | F18: PC | G18: 729.84 | H18: Korea | I18: 0.15 | J18: kg | K18: SCREEN PRINT INK
A19: 3 | B19: 4809.90-1000 | C19: TRANSFER PAPER FOR PROTECTION | D19: 114.88 | E19: 25 | F19: RL | G19: 2872 | H19: Korea | I19: 0.15 | J19: kg | K19: TRANSFER PAPER
B20: GRAND TOTAL : | E20: ==SUM(E17:E19) | G20: ==SUM(G17:G19)
A22: PROFORMA INVOICE FOR PF26S0084SB | B22: PROFORMA INVOICE FOR PF26S0080SB | C22: PROFORMA INVOICE FOR PF26S0080SB | D22: PROFORMA INVOICE FOR PF26S0080SB | E22: PROFORMA INVOICE FOR PF26S0080SB | F22: PROFORMA INVOICE FOR PF26S0080SB | G22: PROFORMA INVOICE FOR PF26S0080SB
A24: No. | B24: ORDER No. | C24: STYLE | D24: QUANTITY | E24: UNIT | F24: DELIVERY
A25: 1 | B25: SB26-S0010 | C25: SAMPLE | D25: 1 | F25: 46095.625
A27: No. | B27: HS No | C27: Hs Name | D27: Unit Price | E27: Q'ty | F27: Unit | G27: Amount | H27: Country | I27: Weight
A28: 1 | B28: 9017.80-1000 | C28: MEASURING TAPE(줄자) WITHOUT METAL TIP | D28: 1.15 | E28: 500 | F28: PC | G28: 575 | H28: Korea | I28: 3.18 | J28: kg | K28: MEASURING TAPE
B29: GRAND TOTAL : | E29: ==SUM(E28:E28) | G29: ==SUM(G28:G28)
A31: PROFORMA INVOICE FOR PO25-1004PK | B31: PROFORMA INVOICE FOR PF26S0080SB | C31: PROFORMA INVOICE FOR PF26S0080SB | D31: PROFORMA INVOICE FOR PF26S0080SB | E31: PROFORMA INVOICE FOR PF26S0080SB | F31: PROFORMA INVOICE FOR PF26S0080SB | G31: PROFORMA INVOICE FOR PF26S0080SB
A33: No. | B33: ORDER No. | C33: STYLE | D33: QUANTITY | E33: UNIT | F33: DELIVERY
A34: 1 | B34: PK25-D0015 | C34: (2025) P1321-000 Men's Trailstar Jacket | D34: 1563 | F34: 46095.625
A35: 2 | B35: PK25-D0016 | C35: (2025) P1322-000 Men's Trailstar Bib | D35: 521 | F35: 46095.625
A36: 3 | B36: PK25-D0071 | C36: (2025) P1348-000 Polaris Pit Coat | D36: 313 | F36: 46095.625
A37: 4 | B37: PK25-D0017 | C37: (2025) P297-003 Youth Ripper 2.0 Jacket | D37: 1248 | F37: 46095.625
A38: 5 | B38: PK25-D0018 | C38: (2025) P299-003 Youth Ripper 2.0 Bib | D38: 520 | F38: 46095.625
A39: 6 | B39: PK25-C0003 | C39: (2026) P203-003 Men’s Switchback Jacket 2.0 | D39: 521 | F39: 46095.625
A40: 7 | B40: PK25-D0082 | C40: (2026) P204-003 Men's Northstar 3.0 Jacket | D40: 1094 | F40: 46095.625
A41: 8 | B41: PK25-C0004 | C41: (2026) P205-003 Women’s Switchback Jacket 2.0 | D41: 551 | F41: 46095.625
A42: 9 | B42: PK25-D0021 | C42: (2026) P216-004 Men's Switchback Bib | D42: 935 | F42: 46095.625
A43: 10 | B43: PK25-D0083 | C43: (2026) P304-001 Women's Northstar 3.0 Jacket | D43: 1352 | F43: 46095.625
A45: No. | B45: HS No | C45: Hs Name | D45: Unit Price | E45: Q'ty | F45: Unit | G45: Amount | H45: Country | I45: Weight
A46: 1 | B46: 5903.20-0000 | C46: CH-31188-C0A2FLW(10K/10K) | D46: 6.29 | E46: 267 | F46: YD | G46: 1679.43 | H46: Korea | I46: 1.7 | J46: kg | K46: CH#3092-P2T | L46: 54"(Cuttable), | M46: POLYESTER 100%
A47: 2 | B47: 5903.20-0000 | C47: CH-31298-C0A2FLW(10K/10K) | D47: 5.15 | E47: 8 | F47: YD | G47: 41.2 | H47: Korea | I47: 0.05 | J47: kg | K47: PU COATED FABRIC | L47: 54"(Cuttable), | M47: POLYESTER 100%
B48: GRAND TOTAL : | E48: ==SUM(E46:E47) | G48: ==SUM(G46:G47)
A50: PROFORMA INVOICE FOR PO25-1005PK | B50: PROFORMA INVOICE FOR PF26S0080SB | C50: PROFORMA INVOICE FOR PF26S0080SB | D50: PROFORMA INVOICE FOR PF26S0080SB | E50: PROFORMA INVOICE FOR PF26S0080SB | F50: PROFORMA INVOICE FOR PF26S0080SB | G50: PROFORMA INVOICE FOR PF26S0080SB
A52: No. | B52: ORDER No. | C52: STYLE | D52: QUANTITY | E52: UNIT | F52: DELIVERY
A53: 1 | B53: PK25-D0078 | C53: (2026) P194-002 Men’s Softshell Jacket | D53: 521 | F53: 46095.625
...

Sheet PAC
A1: PACKING LIST
A2: 1) Shipper/ Exporter: | G2: 8) No & Date of Invoice
A3: Shin Textile Solutions Co., Ltd.
A4: 801,E&C Venture Dreamtower 2, 55, Digital-ro 33-gil, | G4: STB-S26-010 | K4: 46095.625
A5: Guro-gu, Seoul, Korea | G5: 9) Remarks:
A6: TEL :070-4659-3337 FAX :02-6330-2019
A7: 2) Consignee :
A8: SHINTS BVT CO.,LTD VAT:0800006025
A9: PHU TAO RESIDENTIAL AREA, THACH KHOI WARD,
A10: HAI PHONG CITY, VIETNAM
A11: TEL :84-320-3861-727 FAX :84-320-3861-730
A12: XNK-Thy Ha <thyha@shintsbvt.com>
A13: 3) Notify party :
A14: THE SAME AS ABOVE
A16: 4) Port of loading: | D16: 5) Final Destination:
A18: INCHEON, KOREA | D18: HAIPHONG, VIETNAM
A19: 6) Carrier | D19: 7) Sailing on/ or About
A22: 10) Marks and Number of PKGS | D22: 11) Description of Goods | G22: 12) Quantity | I22: 13) Net | J22: 14) Gross | K22: 15) Measurement
I23: Weight | J23: Weight
G24: ( CPT HANOI, VIETNAM )
D25: TOTAL : | G25: ==VLOOKUP("TOTAL",P!A:I,7,0) | I25: =='BVT.INV'!I60 | J25: ==I25*1.1 | K25: ==J25/166
A27: SHINTS BVT
A28: (IN DIA)
D29: MATERIALS FOR GARMENT
A30: STYLE NO.:
A31: ITEM :
A32: Q'TY :
A33: C/T NO. : | D33: TOTAL
A51: TEL NO. : (02)6330-2000~14, (DIR. 6330-2012)
A52: FAX NO. : (02)6330-2019 | H52: 16).Signed by :

Sheet D.PAC
A2: DETAIL PACKING LIST FOR PF26S0080SB
A3: Supplier | B3: MATL CODE | C3: DESCRIPTION | D3: COLOR | E3: SPEC | F3: UNIT | G3: IN-Q'TY | H3: C/T Q'ty | I3: C/T No. | J3: Remark
A4: (MARKET)한성비니루 | B4: S24-26114 | C4: PVC Memory form 1.8mm | D4: White | E4: 140cm | F4: M | G4: 30 | H4: 2 | I4: box-20260312 | K4: 5903.10-0000 | L4: PVC
A5: (MARKET)한성비니루 | B5: S24-61567 | C5: PVC Memory form 3mm | D5: White | E5: 140cm | F5: M | G5: 30 | H5: 0 | I5: box-20260312 | K5: 5903.10-0000 | L5: PVC
A6: TOTAL | C6: BALES | G6: ==SUM(G4:G5) | H6: ==SUM(H4:H5)
A8: DETAIL PACKING LIST FOR PF26S0081SB
A9: Supplier | B9: MATL CODE | C9: DESCRIPTION | D9: COLOR | E9: SPEC | F9: UNIT | G9: IN-Q'TY | H9: C/T Q'ty | I9: C/T No. | J9: Remark
A10: (ZE)제스트 | B10: A22-00044 | C10: INK FOR INK JET PLOTTER(구형기계용) | D10: Key(black) | E10: SES-K IS-6700/KT6400 - INK 1L*12/1CT | F10: PC | G10: 12 | H10: 30 | I10: box-20260311 | K10: 3215.11-4000 | L10: SCREEN PRINT INK
A11: (ZE)제스트 | B11: A22-00045 | C11: INK FOR INK JET PLOTTER(구형기계용) | D11: Magenta | E11: SES-M IS-6700/KT6400 - INK 1L*12/1CT | F11: PC | G11: 12 | H11: 0 | I11: box-20260311 | K11: 3215.11-4000 | L11: SCREEN PRINT INK
A12: (ZE)제스트 | B12: A22-00047 | C12: INK FOR INK JET PLOTTER(구형기계용) | D12: Cyan | E12: SES-C IS-6700/KT6400 - INK 1L*12/1CT | F12: PC | G12: 12 | K12: 3215.11-4000 | L12: SCREEN PRINT INK
A13: (ZE)제스트 | B13: A22-00072 | C13: ITALY INK FOR INK JET PLOTTER(신형기계용) | D13: Cyan | E13: SI1000 EVO-C 1L*12/1CT | F13: PC | G13: 12 | K13: 3215.11-4000 | L13: SCREEN PRINT INK
A14: (ZE)제스트 | B14: A22-00073 | C14: ITALY INK FOR INK JET PLOTTER(신형기계용) | D14: Key(BLK) | E14: SI1000 EVO-K 1L*12/1CT | F14: PC | G14: 12 | K14: 3215.11-4000 | L14: SCREEN PRINT INK
A15: (ZE)제스트 | B15: A22-00100 | C15: TRANSFER PAPER FOR PROTECTION | E15: 20G, 1650MM X 1,020M 24RL/PL | F15: RL | G15: 1 | K15: 4809.90-1000 | L15: TRANSFER PAPER
A16: (ZE)제스트 | B16: A22-00100 | C16: TRANSFER PAPER FOR PROTECTION | E16: 20G, 1650MM X 1,020M 24RL/PL | F16: RL | G16: 24 | K16: 4809.90-1000 | L16: TRANSFER PAPER
A17: TOTAL | C17: BALES | G17: ==SUM(G10:G16) | H17: ==SUM(H10:H16)
A19: DETAIL PACKING LIST FOR PF26S0084SB
A20: Supplier | B20: MATL CODE | C20: DESCRIPTION | D20: COLOR | E20: SPEC | F20: UNIT | G20: IN-Q'TY | H20: C/T Q'ty | I20: C/T No. | J20: Remark
A21: IMPORT-K(BMC) | B21: S23-38000 | C21: MEASURING TAPE(줄자) WITHOUT METAL TIP | E21: 150CM WITH INCH | F21: PC | G21: 500 | H21: 1 | I21: box-20260311 | K21: 9017.80-1000 | L21: MEASURING TAPE
A22: TOTAL | C22: BALES | G22: ==SUM(G21:G21) | H22: ==SUM(H21:H21)
A24: DETAIL PACKING LIST FOR PO25-1004PK
A25: Supplier | B25: MATL CODE | C25: DESCRIPTION | D25: COLOR | E25: SPEC | F25: UNIT | G25: IN-Q'TY | H25: C/T Q'ty | I25: C/T No. | J25: Remark
A26: IMPORT-K(SAMTEX) | B26: M23-02842 | C26: CH-31188-C0A2FLW(10K/10K) | D26: Smoked Pearl 18-0000 TCX | E26: 54"(Cuttable), C0 DWR Version, 100%P, P 610D x P 610D, Dty | F26: YD | G26: 22 | H26: 5 | I26: box-20260312 | J26: PO25-1004/PO25-1005 MIXED BOX | K26: 5903.20-0000 | L26: CH#3092-P2T | N26: POLYESTER 100%
A27: IMPORT-K(SAMTEX) | B27: M23-02842 | C27: CH-31188-C0A2FLW(10K/10K) | D27: Smoked Pearl 18-0000 TCX | E27: 54"(Cuttable), C0 DWR Version, 100%P, P 610D x P 610D, Dty | F27: YD | G27: 245 | H27: 0 | I27: box-20260312 | J27: PO25-1004/PO25-1005 MIXED BOX | K27: 5903.20-0000 | L27: CH#3092-P2T | N27: POLYESTER 100%
A28: IMPORT-K(SAMTEX) | B28: M25-02987 | C28: CH-31298-C0A2FLW(10K/10K) | D28: Very Berry 18- 2336 TCX LD#A | E28: 54"(Cuttable), 100% POLYESTER | F28: YD | G28: 8 | K28: 5903.20-0000 | L28: PU COATED FABRIC | N28: POLYESTER 100%
A29: TOTAL | C29: BALES | G29: ==SUM(G26:G28) | H29: ==SUM(H26:H28)
A31: DETAIL PACKING LIST FOR PO25-1005PK
A32: Supplier | B32: MATL CODE | C32: DESCRIPTION | D32: COLOR | E32: SPEC | F32: UNIT | G32: IN-Q'TY | H32: C/T Q'ty | I32: C/T No. | J32: Remark
A33: IMPORT-K(SAMTEX) | B33: M25-03000 | C33: CH-32046- C0ADWRCIRE | D33: Sharkskin 17- 3914 TCX | E33: 55"(Cuttable), 100% Polyester- C0 DWR (Samtex) | F33: YD | G33: 12 | H33: 0 | I33: box-20260312 | J33: PO25-1004/PO25-1005 MIXED BOX | K33: 5407.69-2000 | L33: PP TWILL PEACH | N33: POLYESTER 100%
A34: IMPORT-K(SAMTEX) | B34: M25-03000 | C34: CH-32046- C0ADWRCIRE | D34: Sharkskin 17- 3914 TCX | E34: 55"(Cuttable), 100% Polyester- C0 DWR (Samtex) | F34: YD | G34: 38 | K34: 5407.69-2000 | L34: PP TWILL PEACH | N34: POLYESTER 100%
A35: TOTAL | C35: BALES | G35: ==SUM(G33:G34) | H35: ==SUM(H33:H34)
A37: DETAIL PACKING LIST FOR PO25-1516NE
A38: Supplier | B38: MATL CODE | C38: DESCRIPTION | D38: COLOR | E38: SPEC | F38: UNIT | G38: IN-Q'TY | H38: C/T Q'ty | I38: C/T No. | J38: Remark
A39: (MB)엠비에프지 | B39: S26-02841 | C39: NATIONAL GEOGRAPHIC SNAP | D39: BLACK | E39: 15MM SG-04 (A+B+C+D part+washer) | F39: SET | G39: 102 | H39: 2 | I39: box-20260310 | J39: PO25-1517/PO25-1518/PO25-1519/PO25-1516 MIXED BOX | K39: 9606.29-9000 | L39: SNAP BUTTON
A40: (MB)엠비에프지 | B40: S26-02841 | C40: NATIONAL GEOGRAPHIC SNAP | D40: BLACK | E40: 15MM SG-04 (A+B+C+D part+washer) | F40: SET | G40: 1196 | H40: 0 | I40: box-20260310 | J40: PO25-1517/PO25-1518/PO25-1519/PO25-1516 MIXED BOX | K40: 9606.29-9000 | L40: SNAP BUTTON
A41: (MB)엠비에프지 | B41: S26-07310 | C41: NATIONAL GEOGRAPHIC WAPPEN | D41: B-MI/KHAKI | E41: 11CM WP-89 | F41: PC | G41: 3 | K41: 3926.90-9000 | L41: SILICON WAPPEN
A42: (MB)엠비에프지 | B42: S26-07311 | C42: NATIONAL GEOGRAPHIC WAPPEN | D42: B-W/SAND | E42: 11CM WP-89 | F42: PC | G42: 3 | K42: 3926.90-9000 | L42: SILICON WAPPEN
A43: (MB)엠비에프지 | B43: S26-07311 | C43: NATIONAL GEOGRAPHIC WAPPEN | D43: B-W/SAND | E43: 11CM WP-89 | F43: PC | G43: 206 | K43: 3926.90-9000 | L43: SILICON WAPPEN
A44: (MB)엠비에프지 | B44: S26-07310 | C44: NATIONAL GEOGRAPHIC WAPPEN | D44: B-MI/KHAKI | E44: 11CM WP-89 | F44: PC | G44: 308 | K44: 3926.90-9000 | L44: SILICON WAPPEN
A45: (YS)유에스소프트 | B45: S24-66373 | C45: NATIONAL GEOGRAPHIC MAIN TAG | E45: (국내) | F45: PC | G45: 485 | H45: 1 | I45: box-20260311 | J45: PO25-1516/PO25-1517/PO25-1518/PO25-1519 MIXED BOX | K45: 4821.10-0000 | L45: HANG TAG
A46: (YS)유에스소프트 | B46: S24-66374 | C46: NATIONAL GEOGRAPHIC TAG PIN | F46: PC | G46: 454 | H46: 0 | I46: box-20260311 | J46: PO25-1516/PO25-1517/PO25-1518/PO25-1519 MIXED BOX | K46: 3926.20-0000 | L46: PLASTIC ACCESSORY FOR GARMENTS
...

Sheet SHINTS
A1: COMMERCIAL INVOICE
A2: 1) Shipper/ Exporter : | G2: 8) No & Date of Invoice
A3: Shin Textile Solutions Co., Ltd.
A4: 801,E&C Venture Dreamtower 2, 55, Digital-ro 33-gil, | G4: STB-S26-010 | K4: 46095.625
A5: Guro-gu, Seoul, Korea | G5: 9) No & Date L/C
A6: TEL :070-4659-3337 FAX :02-6330-2019
A7: 2) Consignee :
A8: SHINTS BVT CO.,LTD VAT:0800006025 | G8: 10) L/C issuing bank
A9: PHU TAO RESIDENTIAL AREA, THACH KHOI WARD,
A10: HAI PHONG CITY, VIETNAM
A11: TEL :84-320-3861-727 FAX :84-320-3861-730 | G11: 11) Remarks:
A12: XNK-Thy Ha <thyha@shintsbvt.com>
A13: 3) Notify party : | I13: FREIGHT CHARGE : | J13: ==1500/65142.43*J29
A14: THE SAME AS ABOVE | I14: INSURANCE CHARGE : | J14: ==J29*1.1*0.026%
I15: 제조자 미상
A16: 4) Port of loading: | D16: 5) Final Destination: | H16: C/T : | I16: 167 | J16: CT
H17: NET : | I17: 3766.19 | J17: KGS
A18: INCHEON, KOREA | D18: HAIPHONG, VIETNAM | H18: GRS : | I18: 4142.809 | J18: KGS
A19: 6) Carrier | D19: 7) Sailing on/ or About
A22: 12) Marks and Number of PKGS | D22: 13) Description of Goods | G22: 14) Quantity/Uint | I22: 15) Unit/price | J22: 16) Amount
D29: TOTAL | J29: ='STS.INVOICE'!G53
A42: TEL NO. : 070-4006-3700~14, (DIR. 070-4006-3727)
A43: FAX NO. : (02)6330-2019 | H43: 17).Signed by :

Sheet IMPORT-K(SAMTEX)
A1: COMMERCIAL INVOICE
A2: 1) Shipper/ Exporter : | G2: 8) No & Date of Invoice
A3: Shin Textile Solutions Co., Ltd.
A4: 801,E&C Venture Dreamtower 2, 55, Digital-ro 33-gil, | G4: STB-S26-010 | K4: 46095.625
A5: Guro-gu, Seoul, Korea | G5: 9) No & Date L/C
A6: TEL :070-4659-3337 FAX :02-6330-2019
A7: 2) Consignee :
A8: SHINTS BVT CO.,LTD VAT:0800006025 | G8: 10) L/C issuing bank
A9: PHU TAO RESIDENTIAL AREA, THACH KHOI WARD,
A10: HAI PHONG CITY, VIETNAM
A11: TEL :84-320-3861-727 FAX :84-320-3861-730 | G11: 11) Remarks:
A12: XNK-Thy Ha <thyha@shintsbvt.com>
A13: 3) Notify party : | I13: FREIGHT CHARGE : | J13: ==1500/65142.43*4022.7300000000005
A14: THE SAME AS ABOVE | I14: INSURANCE CHARGE : | J14: ==4022.7300000000005*1.1*0.026%
A16: 4) Port of loading: | D16: 5) Final Destination: | H16: C/T : | I16: 17 | J16: CT
H17: NET : | I17: 5.26 | J17: KGS
A18: INCHEON, KOREA | D18: HAIPHONG, VIETNAM | H18: GRS : | I18: 5.786 | J18: KGS
A19: 6) Carrier | D19: 7) Sailing on/ or About
A22: 12) Marks and Number of PKGS | D22: 13) Description of Goods | G22: 14) Quantity/Uint | I22: 15) Unit/price | J22: 16) Amount
G24: ( CIF HAIPHONG, VIETNAM )
D26: Desc | G26: Q'ty | H26: Unit | I26: Price | J26: Total
D27: CH-31188-C0A2FLW(10K/10K) | G27: 267 | H27: YD | I27: 6.29 | J27: ==G27*I27 | K27: 1.7
D28: CH-31298-C0A2FLW(10K/10K) | G28: 8 | H28: YD | I28: 5.15 | J28: ==G28*I28 | K28: 0.05
D29: CH-32046- C0ADWRCIRE | G29: 50 | H29: YD | I29: 2.55 | J29: ==G29*I29 | K29: 0.32
D30: SANDWICH AIR MESH (CH-31963-PD) | G30: 524 | H30: YD | I30: 4.15 | J30: ==G30*I30 | K30: 3.19
D31: TOTAL | J31: ==SUM(J27:J30) | K31: ==SUM(K27:K30)
A33: DESC/SPEC | D33: HS CODE | F33: OFFER SPEC
A34: 54"(Cuttable), C0 DWR Version, 100%P, P 610D x P 610D, Dty | D34: 5903.20-0000 | F34: 100% POLYESTER D.T.Y F.YARN WOVEN FABRIC YARM SEPC : P/DTY 305 INVISTA 2PLY*P/DTY 305 INVISTA 2PLY FINISHED : PD/C0 AWR/2LAYER WHITE LAMINATED(10K/10K) WIDTH : 54" WEIGHT : 351GR/YD | L34: CH-31188-C0A2FLW(10K/10K)
A35: 54"(Cuttable), 100% POLYESTER | D35: 5903.20-0000 | F35: 100%POLYESTR F.YARN WOVEN FABRIC US 305D CORDURA 63" WITH IN GREY WOVEN BY SHUTTLESS LOOM FINISH : PD/C0 ADWR/2 LAYER WHITE LAMINATION (10K/10K) W/P : US P/DTY 305D BR 84E/INCH 174GR/YD W/T : US P/DTY 305D BR 52P/INCH 105GR/YD YARN WEIGHT : 279GR/YD TOTAL WEIGHT : 327GR/YD | L35: CH-31298-C0A2FLW(10K/10K)
A36: 55"(Cuttable), 100% Polyester- C0 DWR (Samtex) | D36: 5407.69-2000 | F36: ITEM : CH-32046-C0ADWRCIRE PD/C0 DWR/CIRE YARN : POLY F.YARN 20D SD+POLY F.YARN 20D SD WIDTH : 55" TOTAL WEIGHT: 49GR/YD | L36: CH-32046- C0ADWRCIRE
A37: 52/54" | D37: 6005.37.0000 | F37: 100% POLYESTER P/D YARN : P75D+P30D WIDTH : 52/54" TOTAL WEIGHT: 325GR/YD | L37: SANDWICH AIR MESH (CH-31963-PD)
A43: TEL NO. : 070-4006-3700~14, (DIR. 070-4006-3727)
A44: FAX NO. : (02)6330-2019 | H44: 17).Signed by :

Sheet IMPORT-K(BRISTEX)
A1: COMMERCIAL INVOICE
A2: 1) Shipper/ Exporter : | G2: 8) No & Date of Invoice
A3: Shin Textile Solutions Co., Ltd.
A4: 801,E&C Venture Dreamtower 2, 55, Digital-ro 33-gil, | G4: STB-S26-010 | K4: 46095.625
A5: Guro-gu, Seoul, Korea | G5: 9) No & Date L/C
A6: TEL :070-4659-3337 FAX :02-6330-2019
A7: 2) Consignee :
A8: SHINTS BVT CO.,LTD VAT:0800006025 | G8: 10) L/C issuing bank
A9: PHU TAO RESIDENTIAL AREA, THACH KHOI WARD,
A10: HAI PHONG CITY, VIETNAM
A11: TEL :84-320-3861-727 FAX :84-320-3861-730 | G11: 11) Remarks:
A12: XNK-Thy Ha <thyha@shintsbvt.com>
A13: 3) Notify party : | I13: FREIGHT CHARGE : | J13: ==1500/65142.43*10156
A14: THE SAME AS ABOVE | I14: INSURANCE CHARGE : | J14: ==10156*1.1*0.026%
A16: 4) Port of loading: | D16: 5) Final Destination: | H16: C/T : | I16: 8 | J16: CT
H17: NET : | I17: 5.68 | J17: KGS
A18: INCHEON, KOREA | D18: HAIPHONG, VIETNAM | H18: GRS : | I18: 6.248 | J18: KGS
A19: 6) Carrier | D19: 7) Sailing on/ or About
A22: 12) Marks and Number of PKGS | D22: 13) Description of Goods | G22: 14) Quantity/Uint | I22: 15) Unit/price | J22: 16) Amount
G24: ( CIF HAIPHONG, VIETNAM )
D26: Desc | G26: Q'ty | H26: Unit | I26: Price | J26: Total
D27: (MFWS005)(RIF09)BX-ESK1717-XPL | G27: 790 | H27: YD | I27: 8.75 | J27: ==G27*I27 | K27: 2.51
D28: (MFWS006)(RIF05)BX-ESK1717 | G28: 499 | H28: YD | I28: 6.5 | J28: ==G28*I28 | K28: 3.17
D29: CH-31298-C0A2FLW(10K/10K) | G29: 8 | H29: YD | I29: 5.15 | J29: ==SUM(J27:J28) | K29: ==SUM(K27:K28)
D30: CH-32046- C0ADWRCIRE | G30: 50 | H30: YD | I30: 2.55 | J30: ==G29*I29 | K30: 0.32
D31: SANDWICH AIR MESH (CH-31963-PD) | G31: 524 | H31: YD | I31: 4.15 | J31: ==G30*I30 | K31: 3.19
D32: TOTAL | J32: ==SUM(J27:J30) | K32: ==SUM(K27:K30)
A34: DESC/SPEC | D34: HS CODE | F34: OFFER SPEC
A35: 44/?" | D35: 5903.20-000 | F35: 61% NYLON 31% POLYESTER 8% SPANDEX WEAVE: RIPSTOP WEIGHT: 245GSM,CUTTABLE WIDTH 44" FINISHING: PFC FREE DWR, BLACK PU LAMINATION | L35: (MFWS005)(RIF09)BX-ESK1717-XPL
A36: 42/45", 61%NYLON 31%POLYESTER 8%SPANDEX,WOVEN | D36: 5407.42-0000 | F36: 61$ NYLON 31% POLYESTER 8% SPANDEX WEAVE: RIPSTOP WEIGHT: 200GSM CUTTABLE WIDTH 44" FINISHING: PFCTREE DWR | L36: (MFWS006)(RIF05)BX-ESK1717
A37: 54"(Cuttable), 100% POLYESTER | D37: 5903.20-0000 | F37: 100%POLYESTR F.YARN WOVEN FABRIC US 305D CORDURA 63" WITH IN GREY WOVEN BY SHUTTLESS LOOM FINISH : PD/C0 ADWR/2 LAYER WHITE LAMINATION (10K/10K) W/P : US P/DTY 305D BR 84E/INCH 174GR/YD W/T : US P/DTY 305D BR 52P/INCH 105GR/YD YARN WEIGHT : 279GR/YD TOTAL WEIGHT : 327GR/YD | L37: CH-31298-C0A2FLW(10K/10K)
A38: 55"(Cuttable), 100% Polyester- C0 DWR (Samtex) | D38: 5407.69-2000 | F38: ITEM : CH-32046-C0ADWRCIRE PD/C0 DWR/CIRE YARN : POLY F.YARN 20D SD+POLY F.YARN 20D SD WIDTH : 55" TOTAL WEIGHT: 49GR/YD | L38: CH-32046- C0ADWRCIRE
A39: 52/54" | D39: 6005.37.0000 | F39: 100% POLYESTER P/D YARN : P75D+P30D WIDTH : 52/54" TOTAL WEIGHT: 325GR/YD | L39: SANDWICH AIR MESH (CH-31963-PD)
A45: TEL NO. : 070-4006-3700~14, (DIR. 070-4006-3727)
A46: FAX NO. : (02)6330-2019 | H46: 17).Signed by :

Sheet IMPORT-K(TS COMPANY)
A1: COMMERCIAL INVOICE
A2: 1) Shipper/ Exporter : | G2: 8) No & Date of Invoice
A3: Shin Textile Solutions Co., Ltd.
A4: 801,E&C Venture Dreamtower 2, 55, Digital-ro 33-gil, | G4: STB-S26-010 | K4: 46095.625
A5: Guro-gu, Seoul, Korea | G5: 9) No & Date L/C
A6: TEL :070-4659-3337 FAX :02-6330-2019
A7: 2) Consignee :
A8: SHINTS BVT CO.,LTD VAT:0800006025 | G8: 10) L/C issuing bank
A9: PHU TAO RESIDENTIAL AREA, THACH KHOI WARD,
A10: HAI PHONG CITY, VIETNAM
A11: TEL :84-320-3861-727 FAX :84-320-3861-730 | G11: 11) Remarks:
A12: XNK-Thy Ha <thyha@shintsbvt.com>
A13: 3) Notify party : | I13: FREIGHT CHARGE : | J13: ==1500/65142.43*42.32
A14: THE SAME AS ABOVE | I14: INSURANCE CHARGE : | J14: ==42.32*1.1*0.026%
A16: 4) Port of loading: | D16: 5) Final Destination: | H16: C/T : | I16: 7 | J16: CT
H17: NET : | I17: 1.08 | J17: KGS
A18: INCHEON, KOREA | D18: HAIPHONG, VIETNAM | H18: GRS : | I18: 1.188 | J18: KGS
A19: 6) Carrier | D19: 7) Sailing on/ or About
A22: 12) Marks and Number of PKGS | D22: 13) Description of Goods | G22: 14) Quantity/Uint | I22: 15) Unit/price | J22: 16) Amount
G24: ( CIF HAIPHONG, VIETNAM )
D26: Desc | G26: Q'ty | H26: Unit | I26: Price | J26: Total
D27: (TSR-C7907) Rib 1X1 | G27: 4232 | H27: PC | I27: 0.01 | J27: ==G27*I27 | K27: 1.08
D28: CH-31298-C0A2FLW(10K/10K) | G28: 8 | H28: YD | I28: 5.15 | J28: ==SUM(J27:J27) | K28: ==SUM(K27:K27)
D29: CH-32046- C0ADWRCIRE | G29: 50 | H29: YD | I29: 2.55 | J29: ==G29*I29 | K29: 0.32
D30: SANDWICH AIR MESH (CH-31963-PD) | G30: 524 | H30: YD | I30: 4.15 | J30: ==G30*I30 | K30: 3.19
D31: TOTAL | J31: ==SUM(J27:J30) | K31: ==SUM(K27:K30)
A33: DESC/SPEC | D33: HS CODE | F33: OFFER SPEC
A34: size S, 15.5x23cm (heighxwidth), 82%COTTON 14%POLYESTER 4%SPAN | D34: 6006.90-0000 | F34: ITEM : TSR-C7907 RIB 1X1 RIB KNIT FABRIC 82%COTTON 14%POLYESTER 4%SPAN | L34: (TSR-C7907) Rib 1X1
A35: size XL, 15.5x26cm (heighxwidth), 82%COTTON 14%POLYESTER 4%SPAN | D35: 6006.90-0000 | F35: ITEM : TSR-C7907 RIB 1X1 RIB KNIT FABRIC 82%COTTON 14%POLYESTER 4%SPAN | L35: (TSR-C7907) Rib 1X1
A36: size 2XL, 15.5x27cm (heighxwidth), 82%COTTON 14%POLYESTER 4%SPAN | D36: 6006.90-0000 | F36: ITEM : TSR-C7907 RIB 1X1 RIB KNIT FABRIC 82%COTTON 14%POLYESTER 4%SPAN | L36: (TSR-C7907) Rib 1X1
A37: size 3XL, 15.5x28cm (heighxwidth), 82%COTTON 14%POLYESTER 4%SPAN | D37: 6006.90-0000 | F37: ITEM : TSR-C7907 RIB 1X1 RIB KNIT FABRIC 82%COTTON 14%POLYESTER 4%SPAN | L37: (TSR-C7907) Rib 1X1
A38: size XS, 15X22cm (heighxwidth), 82%COTTON 14%POLYESTER 4%SPAN | D38: 6006.90-0000 | F38: ITEM : TSR-C7907 RIB 1X1 RIB KNIT FABRIC 82%COTTON 14%POLYESTER 4%SPAN | L38: (TSR-C7907) Rib 1X1
A39: size S, 15x23cm (heighxwidth), 82%COTTON 14%POLYESTER 4%SPAN | D39: 6006.90-0000 | F39: ITEM : TSR-C7907 RIB 1X1 RIB KNIT FABRIC 82%COTTON 14%POLYESTER 4%SPAN | L39: (TSR-C7907) Rib 1X1
A40: size XS, 15x21cm (heighxwidth), 82%COTTON 14%POLYESTER 4%SPAN | D40: 6006.90-0000 | F40: ITEM : TSR-C7907 RIB 1X1 RIB KNIT FABRIC 82%COTTON 14%POLYESTER 4%SPAN | L40: (TSR-C7907) Rib 1X1
A41: 54"(Cuttable), 100% POLYESTER | D41: 5903.20-0000 | F41: 100%POLYESTR F.YARN WOVEN FABRIC US 305D CORDURA 63" WITH IN GREY WOVEN BY SHUTTLESS LOOM FINISH : PD/C0 ADWR/2 LAYER WHITE LAMINATION (10K/10K) W/P : US P/DTY 305D BR 84E/INCH 174GR/YD W/T : US P/DTY 305D BR 52P/INCH 105GR/YD YARN WEIGHT : 279GR/YD TOTAL WEIGHT : 327GR/YD | L41: CH-31298-C0A2FLW(10K/10K)
A42: 55"(Cuttable), 100% Polyester- C0 DWR (Samtex) | D42: 5407.69-2000 | F42: ITEM : CH-32046-C0ADWRCIRE PD/C0 DWR/CIRE YARN : POLY F.YARN 20D SD+POLY F.YARN 20D SD WIDTH : 55" TOTAL WEIGHT: 49GR/YD | L42: CH-32046- C0ADWRCIRE
A43: 52/54" | D43: 6005.37.0000 | F43: 100% POLYESTER P/D YARN : P75D+P30D WIDTH : 52/54" TOTAL WEIGHT: 325GR/YD | L43: SANDWICH AIR MESH (CH-31963-PD)
A49: TEL NO. : 070-4006-3700~14, (DIR. 070-4006-3727)
A50: FAX NO. : (02)6330-2019 | H50: 17).Signed by :
