Workbook

Sheet STS.INVOICE
A1: PROFORMA INVOICE FOR SHINTS
A3: No | B3: HS_No | C3: Matl Name | D3: Unit Price | E3: Q'ty | F3: Unit | G3: Amount | H3: Country | I3: Weight | K3: Width | L3: Composition
A4: 1 | B4: 6005.35.0000 | C4: DH-184 BRUSHED TRICOT | D4: 0.91 | E4: 970 | F4: YD | G4: 882.7 | H4: Korea | I4: 8.37 | J4: kg | K4: 58/60" | L4: POLYESTER 100%
A5: 2 | B5: 6005.37.0000 | C5: DH-190-22 (2:2 AIR MESH) | D5: 1.08 | E5: 125 | F5: YD | G5: 135 | H5: Korea | I5: 1.08 | J5: kg | L5: POLYESTER 100%
A6: 3 | B6: 5603.93-0000 | C6: WARM LITE WA-70 | D6: 3.35 | E6: 4280 | F6: KG | G6: 14338 | H6: Korea | I6: 36.91 | J6: kg | L6: POLYESTER 100%
A7: 4 | B7: 4821.10-0000 | C7: (MPHG025)(HTG LAYER CL-LP) LASPORTIVA LAYER HANGTAG CLIMBING LAYERS | D7: 0.04 | E7: 4461 | F7: PC | G7: 178.44 | H7: Korea | I7: 38.47 | J7: kg
A8: 5 | B8: 4821.10-0000 | C8: (MPHG030)(HTG LINE CL) LASPORTIVA LINE HANGTAG CLIMBING | D8: 0.07 | E8: 4461 | F8: PC | G8: 312.27 | H8: Korea | I8: 38.47 | J8: kg
A9: 6 | B9: 4821.10-0000 | C9: (MPHG138) Disclaimer leaflet | D9: 0.09 | E9: 4461 | F9: PC | G9: 401.49 | H9: Korea | I9: 38.47 | J9: kg
A10: 7 | B10: 3923.50-0000 | C10: 1 HOLE STOPPER | D10: 0.04 | E10: 16916 | F10: PC | G10: 676.64 | H10: Korea | I10: 145.87 | J10: kg
A11: 8 | B11: 3923.50-0000 | C11: 2 HOLE STOPPER | D11: 0.06 | E11: 19458 | F11: PC | G11: 1167.48 | H11: Korea | I11: 167.79 | J11: kg
A12: 9 | B12: 3923.50-0000 | C12: BEAD STOPPER | D12: 0.0163 | E12: 57792 | F12: PC | G12: 942.01 | H12: Korea | I12: 498.35 | J12: kg
A13: 10 | B13: 5806.32-0000 | C13: CQR NECK TAPE | D13: 0.03 | E13: 24000 | F13: YD | G13: 720 | H13: Korea | I13: 206.96 | J13: kg
A14: 11 | B14: 6117.80-9000 | C14: ELASTIC BIAS TAPE | D14: 0.01 | E14: 30940 | F14: YD | G14: 309.4 | H14: Korea | I14: 266.8 | J14: kg
A15: 12 | B15: 5607.50-0000 | C15: ELASTIC NYLON STRING | D15: 0.0616 | E15: 30237 | F15: YD | G15: 1862.6 | H15: Korea | I15: 260.73 | J15: kg
A16: 13 | B16: 5607.50-0000 | C16: ELASTIC NYLON STRING 2MM | D16: 0.0828 | E16: 5198 | F16: M | G16: 430.39 | H16: Korea | I16: 44.83 | J16: kg
A17: 14 | B17: 8308.10-2000 | C17: EYELET(N) | D17: 0.02 | E17: 74268 | F17: SET | G17: 1485.36 | H17: Korea | I17: 640.43 | J17: kg
A18: 15 | B18: 5601.22-0000 | C18: FIBERBALL WB300 | D18: 4.96 | E18: 720 | F18: KG | G18: 3571.2 | H18: Korea | I18: 6.21 | J18: kg
... A31: 28 | B31: 6117.80-9000 | C31: WOOL ELASTIC BIAS TAPE | D31: 0.17 | E31: 15359 | F31: M | G31: 2611.03 | H31: Korea | I31: 132.39 | J31: kg
B32: GRAND TOTAL : | E32: ==SUM(E4:E31) | G32: ==SUM(G4:G31) | I32: ==SUM(I4:I31) | J32: kg

Sheet P
A1: DETAIL PACKING LIST FOR
A3: Supplier | B3: DESCRIPTION | C3: COLOR | D3: SPEC | E3: UNIT | F3: IN-Q'TY | G3: C/T Q'ty | H3: C/T No. | I3: Remark
A4: (TL)태광엘앤티 | B4: MUSINSA GUARANTEE TAG | C4: BLACK | D4: MSTG-02-B 품질보증택 (NEW from 26SS) | E4: PC | F4: 4235 | G4: 20 | H4: box-20260303 | I4: EO26-0014/EO26-0015/EO26-0016/EO26-0017/EO26-0018/EO26-0019/EO26-0021/EO26-0022/EO26-0020/EO26-0053 MIXED BOX
A5: (TL)태광엘앤티 | B5: MUSINSA HANG TAG | C5: BLACK | D5: MSTG-02-A | E5: PC | F5: 4235
A6: (TL)태광엘앤티 | B6: SIZE STICKER ROUND | C6: BLACK/WHITE | D6: 25MM / SIZE 2XL | E6: PC | F6: 635
A7: (TL)태광엘앤티 | B7: SIZE STICKER ROUND | C7: BLACK/WHITE | D7: 25MM / SIZE S | E7: PC | F7: 647
A8: (TL)태광엘앤티 | B8: SIZE STICKER ROUND | C8: BLACK/WHITE | D8: 25MM / SIZE XL | E8: PC | F8: 921
A9: (TL)태광엘앤티 | B9: SIZE STICKER ROUND | C9: BLACK/WHITE | D9: 25MM / SIZE M | E9: PC | F9: 995
A10: (TL)태광엘앤티 | B10: SIZE STICKER ROUND | C10: BLACK/WHITE | D10: 25MM / SIZE L | E10: PC | F10: 1038
A11: (TL)태광엘앤티 | B11: TAG PIN | C11: BLACK | D11: 택고리무지락검정 | E11: PC | F11: 4203
A12: (TL)태광엘앤티 | B12: MUSINSA GUARANTEE TAG | C12: BLACK | D12: MSTG-02-B 품질보증택 (NEW from 26SS) | E12: PC | F12: 7397
A13: (TL)태광엘앤티 | B13: MUSINSA HANG TAG | C13: BLACK | D13: MSTG-02-A | E13: PC | F13: 7397
A14: (TL)태광엘앤티 | B14: MUSINSA MAIN LABEL | C14: BLACK | D14: XS, MSS-LB-02 (NEW from 26SS) 끼워박는 라벨 | E14: PC | F14: 214
A15: (TL)태광엘앤티 | B15: MUSINSA MAIN LABEL | C15: BLACK | D15: 2XL, MSS-LB-02 (NEW from 26SS) 끼워박는 라벨 | E15: PC | F15: 1067
A16: (TL)태광엘앤티 | B16: MUSINSA MAIN LABEL | C16: BLACK | D16: S, MSS-LB-02 (NEW from 26SS) 끼워박는 라벨 | E16: PC | F16: 1100
... A107: (TL)태광엘앤티 | B107: TAG PIN | C107: BLACK | D107: 택고리무지락검정 | E107: PC | F107: 2103
A108: IMPORT-K(CMS GLOBAL) | B108: ELASTIC NYLON STRING | C108: HEATHER DARK GREY(=CHARCOAL) | D108: 3MM | E108: YD | F108: 2352 | G108: 14 | H108: box-20260310 | I108: EO26-0003/EO26-0004 MIXED BOX
A109: IMPORT-K(CMS GLOBAL) | B109: ELASTIC NYLON STRING | C109: SOIL GREEN(=ARMY GREEN) | D109: 3MM | E109: YD | F109: 2372
A110: IMPORT-K(CMS GLOBAL) | B110: ELASTIC NYLON STRING | C110: OPERATOR NAVY | D110: 3MM | E110: YD | F110: 2576
A111: IMPORT-K(CMS GLOBAL) | B111: ELASTIC NYLON STRING | C111: COYOTE | D111: 3MM | E111: YD | F111: 2903
A112: IMPORT-K(CMS GLOBAL) | B112: ELASTIC NYLON STRING | C112: BLK | D112: 3MM | E112: YD | F112: 9825
A113: IMPORT-K(CMS GLOBAL) | B113: EYELET(N) | C113: MATTE BLACK NICKEL | D113: #3 (INNER HOLE 6MM)(+1WASHER) | E113: SET | F113: 55476
A114: IMPORT-K(CMS GLOBAL) | B114: O-RING BEAD STOPPER | C114: SOIL GREEN(=ARMY GREEN) | D114: CMS-298 | E114: PC | F114: 4830
A115: IMPORT-K(CMS GLOBAL) | B115: O-RING BEAD STOPPER | C115: OPERATOR NAVY | D115: CMS-298 | E115: PC | F115: 4851
A116: IMPORT-K(CMS GLOBAL) | B116: O-RING BEAD STOPPER | C116: COYOTE | D116: CMS-298 | E116: PC | F116: 5302
A117: IMPORT-K(CMS GLOBAL) | B117: O-RING BEAD STOPPER | C117: HEATHER DARK GREY(=CHARCOAL) | D117: CMS-298 | E117: PC | F117: 5650
A118: IMPORT-K(CMS GLOBAL) | B118: O-RING BEAD STOPPER | C118: BLACK | D118: CMS-298 | E118: PC | F118: 14611
A119: IMPORT-K(CMS GLOBAL) | B119: STOPPER WITH TAPE HOLE | C119: OPERATOR NAVY | D119: CMS-375 | E119: PC | F119: 4741
A120: IMPORT-K(CMS GLOBAL) | B120: STOPPER WITH TAPE HOLE | C120: SOIL GREEN(=ARMY GREEN) | D120: CMS-375 | E120: PC | F120: 4830
... A136: IMPORT-K(CMS GLOBAL) | B136: STOPPER WITH TAPE HOLE | C136: HUNTING CAMO | D136: CMS-375 | E136: PC | F136: 4127
A137: IMPORT-K(CMS GLOBAL) | B137: BEAD STOPPER | C137: DGR | D137: MSS-BE-01(=CMS-360 눈물비드) | E137: PC | F137: 3185 | G137: 25 | H137: box-20260310 | I137: EO26-0022/EO26-0021/EO26-0020/EO26-0019/EO26-0018/EO26-0017/EO26-0016/EO26-0015/EO26-0014/EO26-0053 MIXED BOX
A138: IMPORT-K(CMS GLOBAL) | B138: BEAD STOPPER | C138: DUE | D138: MSS-BE-01(=CMS-360 눈물비드) | E138: PC | F138: 4453
A139: IMPORT-K(CMS GLOBAL) | B139: BEAD STOPPER | C139: LGR | D139: MSS-BE-01(=CMS-360 눈물비드) | E139: PC | F139: 5086
A140: IMPORT-K(CMS GLOBAL) | B140: STOPPER WITH TAB | C140: DGR | D140: MSS-ST-01 (맥주컵 스토퍼) | E140: PC | F140: 3185
A141: IMPORT-K(CMS GLOBAL) | B141: STOPPER WITH TAB | C141: DUE | D141: MSS-ST-01 (맥주컵 스토퍼) | E141: PC | F141: 4453
A142: IMPORT-K(CMS GLOBAL) | B142: STOPPER WITH TAB | C142: LGR | D142: MSS-ST-01 (맥주컵 스토퍼) | E142: PC | F142: 5086
A143: IMPORT-K(CMS GLOBAL) | B143: WOOL ELASTIC BIAS TAPE | C143: DGR | D143: 20MM 울접밴드 | E143: M | F143: 1668
A144: IMPORT-K(CMS GLOBAL) | B144: WOOL ELASTIC BIAS TAPE | C144: LGR | D144: 20MM 울접밴드 | E144: M | F144: 3916
A145: IMPORT-K(CMS GLOBAL) | B145: 1 HOLE STOPPER | C145: BLACK | D145: MSS-ST-07 | E145: PC | F145: 14793
A146: IMPORT-K(CMS GLOBAL) | B146: 2 HOLE STOPPER | C146: BLACK | D146: MSS-ST-02 | E146: PC | F146: 14793
...

Sheet C.INV
A1: COMMERCIAL INVOICE
A2: 1) Shipper/ Exporter : | G2: 8) No & Date of Invoice
A3: Shin Textile Solutions Co., Ltd.
A4: 801,E&C Venture Dreamtower 2, 55, Digital-ro 33-gil, | G4: STE-S26-005 | K4: 46093.625
A5: Guro-gu, Seoul, Korea | G5: 9) No & Date L/C
A6: TEL :070-4659-3337 FAX :02-6330-2019
A7: 2) Consignee :
A8: SHINTS ETP GARMENT PLC TIN:0040614058 | G8: 10) L/C issuing bank
A9: BOLE LEMI INDUSTRY PARK, BOLE LEMI,
A10: BOLE SUB-CITY, WOREDA 11, ADDIS ABABA, ETHIOPIA
A11: TEL :+251 118 29 83 07 FAX :+251 92 058 0957 | G11: 11) Remarks:
A12: XNK-Thy Ha <thyha@shintsbvt.com>
A13: 3) Notify party :
A14: THE SAME AS ABOVE
A16: 4) Port of loading: | D16: 5) Final Destination:
A18: INCHEON, KOREA | D18: ADDIS ABABA, ETHIOPIA
A19: 6) Carrier | D19: 7) Sailing on/ or About
A22: 12) Marks and Number of PKGS | D22: 13) Description of Goods | G22: 14) Quantity/Uint | I22: 15) Unit/price | J22: 16) Amount
G24: (CIF ADDIS ABABA, ETHIOIA)
A25: SHINTS BVT
A26: (IN DIA)
D27: MATERIALS FOR GARMENT
A28: STYLE NO.:
A29: ITEM :
A30: Q'TY :
A31: C/T NO. : | D31: TOTAL | J31: ==VLOOKUP("GRAND TOTAL :",BVT.INV!B:I,6,0)
A40: TEL NO. : 070-4006-3700~14, (DIR. 070-4006-3727)
A41: FAX NO. : (02)6330-2019 | H41: 17).Signed by :

Sheet BVT.INV
A1: PROFORMA INVOICE FOR BVT
A3: No | B3: HS_No | C3: Matl Name | D3: Unit Price | E3: Q'ty | F3: Unit | G3: Amount | H3: Country | I3: Weight | K3: HS Name | L3: Width | M3: Composition
A4: 1 | B4: 6005.35.0000 | C4: DH-184 BRUSHED TRICOT | D4: 0.91 | E4: 970 | F4: YD | G4: 882.7 | H4: Korea | I4: 8.37 | J4: kg | K4: TS-0258(MICRO BRUSHED) | L4: 58/60" | M4: POLYESTER 100%
A5: 2 | B5: 6005.37.0000 | C5: DH-190-22 (2:2 AIR MESH) | D5: 1.08 | E5: 125 | F5: YD | G5: 135 | H5: Korea | I5: 1.08 | J5: kg | K5: AIR MESH | M5: POLYESTER 100%
A6: 3 | B6: 5603.93-0000 | C6: WARM LITE WA-70 | D6: 3.35 | E6: 4280 | F6: KG | G6: 14338 | H6: Korea | I6: 36.91 | J6: kg | K6: EXKIN PADDING(100G) | M6: POLYESTER 100%
A7: 4 | B7: 4821.10-0000 | C7: (MPHG025)(HTG LAYER CL-LP) LASPORTIVA LAYER HANGTAG CLIMBING LAYERS | D7: 0.04 | E7: 4461 | F7: PC | G7: 178.44 | H7: Korea | I7: 38.47 | J7: kg | K7: HANG TAG
A8: 5 | B8: 4821.10-0000 | C8: (MPHG030)(HTG LINE CL) LASPORTIVA LINE HANGTAG CLIMBING | D8: 0.07 | E8: 4461 | F8: PC | G8: 312.27 | H8: Korea | I8: 38.47 | J8: kg | K8: HANG TAG
A9: 6 | B9: 4821.10-0000 | C9: (MPHG138) Disclaimer leaflet | D9: 0.09 | E9: 4461 | F9: PC | G9: 401.49 | H9: Korea | I9: 38.47 | J9: kg | K9: HANG TAG
A10: 7 | B10: 3923.50-0000 | C10: 1 HOLE STOPPER | D10: 0.04 | E10: 16916 | F10: PC | G10: 676.64 | H10: Korea | I10: 145.87 | J10: kg | K10: PLASTIC STOPPER
A11: 8 | B11: 3923.50-0000 | C11: 2 HOLE STOPPER | D11: 0.06 | E11: 19458 | F11: PC | G11: 1167.48 | H11: Korea | I11: 167.79 | J11: kg | K11: PLASTIC STOPPER
A12: 9 | B12: 3923.50-0000 | C12: BEAD STOPPER | D12: 0.0163 | E12: 57792 | F12: PC | G12: 942.01 | H12: Korea | I12: 498.35 | J12: kg | K12: PLASTIC STOPPER
A13: 10 | B13: 5806.32-0000 | C13: CQR NECK TAPE | D13: 0.03 | E13: 24000 | F13: YD | G13: 720 | H13: Korea | I13: 206.96 | J13: kg | K13: WOVEN TAPE
A14: 11 | B14: 6117.80-9000 | C14: ELASTIC BIAS TAPE | D14: 0.01 | E14: 30940 | F14: YD | G14: 309.4 | H14: Korea | I14: 266.8 | J14: kg | K14: ELASTIC BIAS TAPE
A15: 12 | B15: 5607.50-0000 | C15: ELASTIC NYLON STRING | D15: 0.0616 | E15: 30237 | F15: YD | G15: 1862.6 | H15: Korea | I15: 260.73 | J15: kg | K15: STRING
A16: 13 | B16: 5607.50-0000 | C16: ELASTIC NYLON STRING 2MM | D16: 0.0828 | E16: 5198 | F16: M | G16: 430.39 | H16: Korea | I16: 44.83 | J16: kg | K16: STRING
A17: 14 | B17: 8308.10-2000 | C17: EYELET(N) | D17: 0.02 | E17: 74268 | F17: SET | G17: 1485.36 | H17: Korea | I17: 640.43 | J17: kg | K17: METAL EYELET
A18: 15 | B18: 5601.22-0000 | C18: FIBERBALL WB300 | D18: 4.96 | E18: 720 | F18: KG | G18: 3571.2 | H18: Korea | I18: 6.21 | J18: kg | K18: BALL PADDING
... A31: 28 | B31: 6117.80-9000 | C31: WOOL ELASTIC BIAS TAPE | D31: 0.17 | E31: 15359 | F31: M | G31: 2611.03 | H31: Korea | I31: 132.39 | J31: kg | K31: ELASTIC BIAS TAPE
B32: GRAND TOTAL : | E32: ==SUM(E4:E31) | G32: ==SUM(G4:G31) | I32: ==SUM(I4:I31) | J32: kg

Sheet D.INV
A1: PROFORMA INVOICE FOR EO25-0248MY | I1: STE-S26-005
A3: No. | B3: ORDER No. | C3: STYLE | D3: QUANTITY | E3: UNIT | F3: DELIVERY
A4: 1 | B4: MY25ED0243 | C4: CQ-TOK002 POLO SHIRT (안은지) | D4: 31635 | F4: 46093.625
A5: 2 | B5: MY25ED0252 | C5: CQ-TOK002 POLO SHIRT (안은지) | D5: 20374 | F5: 46093.625
A7: No. | B7: HS No | C7: Hs Name | D7: Unit Price | E7: Q'ty | F7: Unit | G7: Amount | H7: Country | I7: Weight
B9: GRAND TOTAL : | E9: ==SUM(E8:E8) | G9: ==SUM(G8:G8)
A11: PROFORMA INVOICE FOR EO25-0249MY | B11: PROFORMA INVOICE FOR EO25-0248MY | C11: PROFORMA INVOICE FOR EO25-0248MY | D11: PROFORMA INVOICE FOR EO25-0248MY | E11: PROFORMA INVOICE FOR EO25-0248MY | F11: PROFORMA INVOICE FOR EO25-0248MY | G11: PROFORMA INVOICE FOR EO25-0248MY
A13: No. | B13: ORDER No. | C13: STYLE | D13: QUANTITY | E13: UNIT | F13: DELIVERY
A14: 1 | B14: MY25ED0249 | C14: CQ-TOS101 INTERLOCK MESH CREWNECK SHIRT (안은지) | D14: 14662 | F14: 46093.625
A15: 2 | B15: MY25ED0250 | C15: CQ-TOS101 INTERLOCK MESH CREWNECK SHIRT (안은지) | D15: 16747 | F15: 46093.625
A16: 3 | B16: MY25ED0251 | C16: CQ-TOS101 INTERLOCK MESH CREWNECK SHIRT (안은지) | D16: 6309 | F16: 46093.625
A18: No. | B18: HS No | C18: Hs Name | D18: Unit Price | E18: Q'ty | F18: Unit | G18: Amount | H18: Country | I18: Weight
B20: GRAND TOTAL : | E20: ==SUM(E19:E19) | G20: ==SUM(G19:G19)
A22: PROFORMA INVOICE FOR EO25-0250MY | B22: PROFORMA INVOICE FOR EO25-0248MY | C22: PROFORMA INVOICE FOR EO25-0248MY | D22: PROFORMA INVOICE FOR EO25-0248MY | E22: PROFORMA INVOICE FOR EO25-0248MY | F22: PROFORMA INVOICE FOR EO25-0248MY | G22: PROFORMA INVOICE FOR EO25-0248MY
A24: No. | B24: ORDER No. | C24: STYLE | D24: QUANTITY | E24: UNIT | F24: DELIVERY
A25: 1 | B25: MY25ED0246 | C25: CQ-TOS120 INTERLOCK MESH(안은지) | D25: 3499 | F25: 46093.625
A26: 2 | B26: MY25ED0248 | C26: CQ-TOS121 INTERLOCK MESH(안은지) | D26: 2142 | F26: 46093.625
A28: No. | B28: HS No | C28: Hs Name | D28: Unit Price | E28: Q'ty | F28: Unit | G28: Amount | H28: Country | I28: Weight
B30: GRAND TOTAL : | E30: ==SUM(E29:E29) | G30: ==SUM(G29:G29)
A32: PROFORMA INVOICE FOR EO25-0251MY | B32: PROFORMA INVOICE FOR EO25-0248MY | C32: PROFORMA INVOICE FOR EO25-0248MY | D32: PROFORMA INVOICE FOR EO25-0248MY | E32: PROFORMA INVOICE FOR EO25-0248MY | F32: PROFORMA INVOICE FOR EO25-0248MY | G32: PROFORMA INVOICE FOR EO25-0248MY
A34: No. | B34: ORDER No. | C34: STYLE | D34: QUANTITY | E34: UNIT | F34: DELIVERY
A35: 1 | B35: MY25ED0244 | C35: CQ-TOS130 INTERLOCK MESH(안은지) | D35: 6223 | F35: 46093.625
A37: No. | B37: HS No | C37: Hs Name | D37: Unit Price | E37: Q'ty | F37: Unit | G37: Amount | H37: Country | I37: Weight
B39: GRAND TOTAL : | E39: ==SUM(E38:E38) | G39: ==SUM(G38:G38)
A41: PROFORMA INVOICE FOR EO25-0252MY | B41: PROFORMA INVOICE FOR EO25-0248MY | C41: PROFORMA INVOICE FOR EO25-0248MY | D41: PROFORMA INVOICE FOR EO25-0248MY | E41: PROFORMA INVOICE FOR EO25-0248MY | F41: PROFORMA INVOICE FOR EO25-0248MY | G41: PROFORMA INVOICE FOR EO25-0248MY
A43: No. | B43: ORDER No. | C43: STYLE | D43: QUANTITY | E43: UNIT | F43: DELIVERY
A44: 1 | B44: MY25ED0245 | C44: CQ-TOK004 POLO SHIRT (안은지) | D44: 7708 | F44: 46093.625
A46: No. | B46: HS No | C46: Hs Name | D46: Unit Price | E46: Q'ty | F46: Unit | G46: Amount | H46: Country | I46: Weight
B48: GRAND TOTAL : | E48: ==SUM(E47:E47) | G48: ==SUM(G47:G47)
A50: PROFORMA INVOICE FOR EO25-0267MY | B50: PROFORMA INVOICE FOR EO25-0248MY | C50: PROFORMA INVOICE FOR EO25-0248MY | D50: PROFORMA INVOICE FOR EO25-0248MY | E50: PROFORMA INVOICE FOR EO25-0248MY | F50: PROFORMA INVOICE FOR EO25-0248MY | G50: PROFORMA INVOICE FOR EO25-0248MY
A52: No. | B52: ORDER No. | C52: STYLE | D52: QUANTITY | E52: UNIT | F52: DELIVERY
A53: 1 | B53: MY25ED0260 | C53: CQ-TOK100 INTERLOCK MESH(안은지) | D53: 6286 | F53: 46093.625
A55: No. | B55: HS No | C55: Hs Name | D55: Unit Price | E55: Q'ty | F55: Unit | G55: Amount | H55: Country | I55: Weight
B57: GRAND TOTAL : | E57: ==SUM(E56:E56) | G57: ==SUM(G56:G56)
A59: PROFORMA INVOICE FOR EO25-0278TR | B59: PROFORMA INVOICE FOR EO25-0248MY | C59: PROFORMA INVOICE FOR EO25-0248MY | D59: PROFORMA INVOICE FOR EO25-0248MY | E59: PROFORMA INVOICE FOR EO25-0248MY | F59: PROFORMA INVOICE FOR EO25-0248MY | G59: PROFORMA INVOICE FOR EO25-0248MY
A61: No. | B61: ORDER No. | C61: STYLE | D61: QUANTITY | E61: UNIT | F61: DELIVERY
A62: 1 | B62: TR25ED0141 | C62: CHAQUETA CAUBERG (WI26 BULK) | D62: 1433 | F62: 46093.625
A63: 2 | B63: TR25ED0139 | C63: CHAQUETA LIENA V02 (WI26 BULK) | D63: 1368 | F63: 46093.625
A64: 3 | B64: TR25ED0137 | C64: CHAQUETA RIPON V02 (WI26 BULK) | D64: 1956 | F64: 46093.625
A65: 4 | B65: TR25ED0142 | C65: CHAQUETA VAALS (WI26 BULK) | D65: 988 | F65: 46093.625
...

Sheet PAC
A1: PACKING LIST
A2: 1) Shipper/ Exporter: | G2: 8) No & Date of Invoice
A3: Shin Textile Solutions Co., Ltd.
A4: 801,E&C Venture Dreamtower 2, 55, Digital-ro 33-gil, | G4: STE-S26-005 | K4: 46093.625
A5: Guro-gu, Seoul, Korea | G5: 9) Remarks:
A6: TEL :070-4659-3337 FAX :02-6330-2019
A7: 2) Consignee :
A8: SHINTS ETP GARMENT PLC TIN:0040614058
A9: BOLE LEMI INDUSTRY PARK, BOLE LEMI,
A10: BOLE SUB-CITY, WOREDA 11, ADDIS ABABA, ETHIOPIA
A11: TEL :+251 118 29 83 07 FAX :+251 92 058 0957
A12: XNK-Thy Ha <thyha@shintsbvt.com>
A13: 3) Notify party :
A14: THE SAME AS ABOVE
A16: 4) Port of loading: | D16: 5) Final Destination:
A18: INCHEON, KOREA | D18: ADDIS ABABA, ETHIOPIA
A19: 6) Carrier | D19: 7) Sailing on/ or About
A22: 10) Marks and Number of PKGS | D22: 11) Description of Goods | G22: 12) Quantity | I22: 13) Net | J22: 14) Gross | K22: 15) Measurement
I23: Weight | J23: Weight
G24: ( CPT HANOI, VIETNAM )
D25: TOTAL : | G25: ==VLOOKUP("TOTAL",P!A:I,7,0) | I25: =='BVT.INV'!I32 | J25: ==I25*1.1 | K25: ==J25/166
A27: SHINTS BVT
A28: (IN DIA)
D29: MATERIALS FOR GARMENT
A30: STYLE NO.:
A31: ITEM :
A32: Q'TY :
A33: C/T NO. : | D33: TOTAL
A51: TEL NO. : (02)6330-2000~14, (DIR. 6330-2012)
A52: FAX NO. : (02)6330-2019 | H52: 16).Signed by :

Sheet D.PAC
A2: DETAIL PACKING LIST FOR EO25-0278TR
A3: Supplier | B3: MATL CODE | C3: DESCRIPTION | D3: COLOR | E3: SPEC | F3: UNIT | G3: IN-Q'TY | H3: C/T Q'ty | I3: C/T No. | J3: Remark
A4: IMPORT-K(DAERIM LND) | B4: S25-139134 | C4: ELASTIC BIAS TAPE | D4: 19-2816TPG BLACKBERRY WINE (YKK#254) | E4: 10MM | F4: YD | G4: 22 | H4: 16 | I4: box-20260303 | J4: EO25-0278/EO26-0041 MIXED BOX | K4: 6117.80-9000 | L4: ELASTIC BIAS TAPE
A5: IMPORT-K(DAERIM LND) | B5: S25-139151 | C5: ELASTIC BIAS TAPE | D5: BLK | E5: 10 MM | F5: YD | G5: 33 | H5: 0 | I5: box-20260303 | J5: EO25-0278/EO26-0041 MIXED BOX | K5: 6117.80-9000 | L5: ELASTIC BIAS TAPE
A6: IMPORT-K(DAERIM LND) | B6: S25-134637 | C6: ELASTIC BIAS TAPE | D6: BLK | E6: 20MM | F6: YD | G6: 47 | K6: 5806.20-0000 | L6: ELASTIC BAND
A7: IMPORT-K(DAERIM LND) | B7: S25-139151 | C7: ELASTIC BIAS TAPE | D7: BLK | E7: 10 MM | F7: YD | G7: 55 | K7: 6117.80-9000 | L7: ELASTIC BIAS TAPE
A8: IMPORT-K(DAERIM LND) | B8: S25-139130 | C8: ELASTIC BIAS TAPE | D8: 16-4411TPG TOURMALINE (YKK#575) | E8: 10MM | F8: YD | G8: 55 | K8: 6117.80-9000 | L8: ELASTIC BIAS TAPE
A9: IMPORT-K(DAERIM LND) | B9: S25-139134 | C9: ELASTIC BIAS TAPE | D9: 19-2816TPG BLACKBERRY WINE (YKK#254) | E9: 10MM | F9: YD | G9: 63 | K9: 6117.80-9000 | L9: ELASTIC BIAS TAPE
A10: IMPORT-K(DAERIM LND) | B10: S25-139131 | C10: ELASTIC BIAS TAPE | D10: 16-1451TPG NASTURTIUM (YKK#138) | E10: 10MM | F10: YD | G10: 66 | K10: 6117.80-9000 | L10: ELASTIC BIAS TAPE
A11: IMPORT-K(DAERIM LND) | B11: S25-139126 | C11: ELASTIC BIAS TAPE | D11: 19-4112TPG STRATIFIED SEA (YKK#075) | E11: 10MM | F11: YD | G11: 77 | K11: 6117.80-9000 | L11: ELASTIC BIAS TAPE
A12: IMPORT-K(DAERIM LND) | B12: S25-139133 | C12: ELASTIC BIAS TAPE | D12: 11-4301TPG LILY WHITE (YKK#841) | E12: 10MM | F12: YD | G12: 77 | K12: 6117.80-9000 | L12: ELASTIC BIAS TAPE
A13: IMPORT-K(DAERIM LND) | B13: S25-139132 | C13: ELASTIC BIAS TAPE | D13: 19-0413TPG DEEP DEPTHS (YKK#237) | E13: 10MM | F13: YD | G13: 80 | K13: 6117.80-9000 | L13: ELASTIC BIAS TAPE
A14: IMPORT-K(DAERIM LND) | B14: S25-134637 | C14: ELASTIC BIAS TAPE | D14: BLK | E14: 20MM | F14: YD | G14: 109 | K14: 5806.20-0000 | L14: ELASTIC BAND
A15: IMPORT-K(DAERIM LND) | B15: S25-139135 | C15: ELASTIC BIAS TAPE | D15: 14-3710TPG ORCHID PETAL (YKK#068) | E15: 10MM | F15: YD | G15: 110 | K15: 6117.80-9000 | L15: ELASTIC BIAS TAPE
A16: IMPORT-K(DAERIM LND) | B16: S25-139135 | C16: ELASTIC BIAS TAPE | D16: 14-3710TPG ORCHID PETAL (YKK#068) | E16: 10MM | F16: YD | G16: 110 | K16: 6117.80-9000 | L16: ELASTIC BIAS TAPE
A17: IMPORT-K(DAERIM LND) | B17: S25-139126 | C17: ELASTIC BIAS TAPE | D17: 19-4112TPG STRATIFIED SEA (YKK#075) | E17: 10MM | F17: YD | G17: 130 | K17: 6117.80-9000 | L17: ELASTIC BIAS TAPE
... A50: IMPORT-K(DAERIM LND) | B50: S25-139129 | C50: ELASTIC BIAS TAPE | D50: URBAN CHIC(19-5004 TPX)(YKK#979) | E50: 10MM | F50: YD | G50: 3760 | K50: 6117.80-9000 | L50: ELASTIC BIAS TAPE
A51: TOTAL | C51: BALES | G51: ==SUM(G4:G50) | H51: ==SUM(H4:H50)
A53: DETAIL PACKING LIST FOR EO26-0003MY
A54: Supplier | B54: MATL CODE | C54: DESCRIPTION | D54: COLOR | E54: SPEC | F54: UNIT | G54: IN-Q'TY | H54: C/T Q'ty | I54: C/T No. | J54: Remark
A55: IMPORT-K(CMS GLOBAL) | B55: S25-75620 | C55: ELASTIC NYLON STRING | D55: HEATHER DARK GREY(=CHARCOAL) | E55: 3MM | F55: YD | G55: 2352 | H55: 14 | I55: box-20260310 | J55: EO26-0003/EO26-0004 MIXED BOX | K55: 5607.50-0000 | L55: STRING
A56: IMPORT-K(CMS GLOBAL) | B56: S25-75622 | C56: ELASTIC NYLON STRING | D56: SOIL GREEN(=ARMY GREEN) | E56: 3MM | F56: YD | G56: 2372 | H56: 0 | I56: box-20260310 | J56: EO26-0003/EO26-0004 MIXED BOX | K56: 5607.50-0000 | L56: STRING
A57: IMPORT-K(CMS GLOBAL) | B57: S25-75621 | C57: ELASTIC NYLON STRING | D57: OPERATOR NAVY | E57: 3MM | F57: YD | G57: 2576 | K57: 5607.50-0000 | L57: STRING
A58: IMPORT-K(CMS GLOBAL) | B58: S25-75619 | C58: ELASTIC NYLON STRING | D58: COYOTE | E58: 3MM | F58: YD | G58: 2903 | K58: 5607.50-0000 | L58: STRING
A59: IMPORT-K(CMS GLOBAL) | B59: S14-44093 | C59: ELASTIC NYLON STRING | D59: BLK | E59: 3MM | F59: YD | G59: 9825 | K59: 5607.50-0000 | L59: STRING
A60: IMPORT-K(CMS GLOBAL) | B60: S24-71022 | C60: EYELET(N) | D60: MATTE BLACK NICKEL | E60: #3 (INNER HOLE 6MM)(+1WASHER) | F60: SET | G60: 55476 | K60: 8308.10-2000 | L60: METAL EYELET
A61: IMPORT-K(CMS GLOBAL) | B61: S25-75661 | C61: O-RING BEAD STOPPER | D61: SOIL GREEN(=ARMY GREEN) | E61: CMS-298 | F61: PC | G61: 4830 | K61: 3923.50-0000 | L61: PLASTIC STOPPER
A62: IMPORT-K(CMS GLOBAL) | B62: S25-75660 | C62: O-RING BEAD STOPPER | D62: OPERATOR NAVY | E62: CMS-298 | F62: PC | G62: 4851 | K62: 3923.50-0000 | L62: PLASTIC STOPPER
A63: IMPORT-K(CMS GLOBAL) | B63: S25-75658 | C63: O-RING BEAD STOPPER | D63: COYOTE | E63: CMS-298 | F63: PC | G63: 5302 | K63: 3923.50-0000 | L63: PLASTIC STOPPER
A64: IMPORT-K(CMS GLOBAL) | B64: S25-75659 | C64: O-RING BEAD STOPPER | D64: HEATHER DARK GREY(=CHARCOAL) | E64: CMS-298 | F64: PC | G64: 5650 | K64: 3923.50-0000 | L64: PLASTIC STOPPER
A65: IMPORT-K(CMS GLOBAL) | B65: S25-75657 | C65: O-RING BEAD STOPPER | D65: BLACK | E65: CMS-298 | F65: PC | G65: 14611 | K65: 3923.50-0000 | L65: PLASTIC STOPPER
A66: IMPORT-K(CMS GLOBAL) | B66: S25-81502 | C66: STOPPER WITH TAPE HOLE | D66: OPERATOR NAVY | E66: CMS-375 | F66: PC | G66: 4741 | K66: 3923.50-0000 | L66: PLASTIC STOPPER
A67: IMPORT-K(CMS GLOBAL) | B67: S25-81425 | C67: STOPPER WITH TAPE HOLE | D67: SOIL GREEN(=ARMY GREEN) | E67: CMS-375 | F67: PC | G67: 4830 | K67: 3923.50-0000 | L67: PLASTIC STOPPER
A68: IMPORT-K(CMS GLOBAL) | B68: S25-75630 | C68: STOPPER WITH TAPE HOLE | D68: COYOTE | E68: CMS-375 | F68: PC | G68: 5432 | K68: 3923.50-0000 | L68: PLASTIC STOPPER
... A70: IMPORT-K(CMS GLOBAL) | B70: S25-81422 | C70: STOPPER WITH TAPE HOLE | D70: BLACK | E70: CMS-375 | F70: PC | G70: 14431 | K70: 3923.50-0000 | L70: PLASTIC STOPPER
A71: TOTAL | C71: BALES | G71: ==SUM(G55:G70) | H71: ==SUM(H55:H70)
A73: DETAIL PACKING LIST FOR EO26-0004MY
A74: Supplier | B74: MATL CODE | C74: DESCRIPTION | D74: COLOR | E74: SPEC | F74: UNIT | G74: IN-Q'TY | H74: C/T Q'ty | I74: C/T No. | J74: Remark
A75: IMPORT-K(CMS GLOBAL) | B75: S23-49334 | C75: ELASTIC NYLON STRING | D75: BLACK | E75: 3MM | F75: M | G75: 1323 | H75: 0 | I75: box-20260310 | J75: EO26-0003/EO26-0004 MIXED BOX | K75: 5607.50-0000 | L75: STRING
A76: IMPORT-K(CMS GLOBAL) | B76: S25-81817 | C76: ELASTIC NYLON STRING | D76: UTILITY CAMO | E76: 3MM | F76: YD | G76: 1855 | K76: 5607.50-0000 | L76: STRING
...

Sheet SHINTS
A1: COMMERCIAL INVOICE
A2: 1) Shipper/ Exporter : | G2: 8) No & Date of Invoice
A3: Shin Textile Solutions Co., Ltd.
A4: 801,E&C Venture Dreamtower 2, 55, Digital-ro 33-gil, | G4: STE-S26-005 | K4: 46093.625
A5: Guro-gu, Seoul, Korea | G5: 9) No & Date L/C
A6: TEL :070-4659-3337 FAX :02-6330-2019
A7: 2) Consignee :
A8: SHINTS ETP GARMENT PLC TIN:0040614058 | G8: 10) L/C issuing bank
A9: BOLE LEMI INDUSTRY PARK, BOLE LEMI,
A10: BOLE SUB-CITY, WOREDA 11, ADDIS ABABA, ETHIOPIA
A11: TEL :+251 118 29 83 07 FAX :+251 92 058 0957 | G11: 11) Remarks:
I13: FREIGHT CHARGE : | J13: ==1500/42959.94*J29
I14: INSURANCE CHARGE : | J14: ==J29*1.1*0.026%
I15: 제조자 미상
A16: Port of loading : | D16: 5) Final Destination: | H16: C/T : | I16: 609 | J16: CT
H17: NET : | I17: 6028.3 | J17: KGS
D18: ADDIS ABABA, ETHIOPIA | H18: GRS : | I18: 6631.13 | J18: KGS
A19: Carrier | D19: 7) Sailing on/ or About
A22: 12) Marks and Number of PKGS | D22: 13) Description of Goods | G22: 14) Quantity/Uint | I22: 15) Unit/price | J22: 16) Amount
H25: * CIF : ADDIS ABABA
D29: TOTAL | J29: ='STS.INVOICE'!G32
A42: TEL NO. : 070-4006-3700~14, (DIR. 070-4006-3727)
A43: FAX NO. : (02)6330-2019 | H43: 17).Signed by :
